Workbook
Name ____CSA8: '[1]INPUT(덕도방향-시점)'!#REF!
Name ____CSA8: '[1]INPUT(덕도방향-시점)'!#REF!
Name ____HSH1: #REF!
Name ____HSH1: #REF!
Name ____HSH2: #REF!
Name ____NP1: #REF!
Name ____NP2: #REF!
Name ____NSH1: #REF!
Name ____NSH2: #REF!
Name ____pl1: #REF!
Name ____PL2: #REF!
Name ____PL3: #REF!
Name ____SBB1: #REF!
Name ____SBB2: #REF!
Name ____SBB3: #REF!
Name ____SBB4: #REF!
Name ____SBB5: #REF!
Name ____SHH1: #REF!
Name ____SHH2: #REF!
Name ____SHH3: #REF!
Name ____TW2: #REF!
Name ___CSA8: '[1]INPUT(덕도방향-시점)'!#REF!
Name ___CSA8: '[1]INPUT(덕도방향-시점)'!#REF!
Name ___HSH1: #REF!
Name ___HSH2: #REF!
Name ___NP1: #REF!
Name ___NP2: #REF!
Name ___NSH1: #REF!
Name ___NSH2: #REF!
Name ___pl1: #REF!
Name ___PL2: #REF!
Name ___PL3: #REF!
Name ___SBB1: #REF!
Name ___SBB2: #REF!
Name ___SBB3: #REF!
Name ___SBB4: #REF!
Name ___SBB5: #REF!
Name ___SHH1: #REF!
Name ___SHH2: #REF!
Name ___SHH3: #REF!
Name ___TW2: #REF!
Name __CSA8: '[1]INPUT(덕도방향-시점)'!#REF!
Name __CSA8: '[1]INPUT(덕도방향-시점)'!#REF!
Name __HSH1: #REF!
Name __HSH2: #REF!
Name __NP1: #REF!
Name __NP2: #REF!
Name __NSH1: #REF!
Name __NSH2: #REF!
Name __pl1: #REF!
Name __PL2: #REF!
Name __PL3: #REF!
Name __SBB1: #REF!
Name __SBB2: #REF!
Name __SBB3: #REF!
Name __SBB4: #REF!
Name __SBB5: #REF!
Name __SHH1: #REF!
Name __SHH2: #REF!
Name __SHH3: #REF!

Sheet 분양개요
A2: 2. 분양개요
A4: 1. 분양수입금
A5: 구 분 | B5: 평형/층별 | D5: 분양단가 | F5: 분양금 | H5: 세대수/평 | J5: 총분양금 | L5: 비고
A6: 아파트A | B6: =I50 -> 25.285975 | C6: 평형 | D6: 14000 | F6: =B6*D6 -> 354003.65 | H6: 336 | J6: =F6*H6 -> 1.1894523e+08
A7: 아파트b | B7: =I51 -> 34.542475 | C7: 평형 | D7: 14000 | F7: =B7*D7 -> 483594.65 | H7: =B51 -> 1549 | J7: =F7*H7 -> 7.4908811e+08
A8: 아파트C | B8: =I52 -> 0 | C8: 평형 | F8: =B8*D8 -> 0 | J8: =F8*H8 -> 0
A9: 아파트D | B9: =I53 -> 0 | C9: 평형 | F9: =B9*D9 -> 0 | J9: =SUM(F9*H9) -> 0
A10: 아파트E | B10: =I54 -> 0 | C10: 평형 | F10: =B10*D10 -> 0 | J10: =SUM(F10*H10) -> 0
A11: 아파트F | B11: =I55 -> 0 | C11: 평형 | F11: =B11*D11 -> 0 | H11: =SUM(B55) -> 0 | J11: =SUM(F11*H11) -> 0
A12: 아파트H | B12: =I56 -> 0 | C12: 평형 | F12: =B12*D12 -> 0 | H12: =SUM(B56) -> 0 | J12: =SUM(F12*H12) -> 0
A13: 아파트G | B13: =I57 -> 0 | C13: 평형 | F13: =B13*D13 -> 0 | H13: =SUM(B57) -> 0 | J13: =SUM(F13*H13) -> 0
A14: 아파트G | B14: =I58 -> 0 | C14: 평형 | F14: =B14*D14 -> 0 | H14: =SUM(B58) -> 0 | J14: =SUM(F14*H14) -> 0
B15: 소계 | H15: =SUM(H6:I14) -> 1885 | J15: =SUM(J6:K14) -> 8.6803334e+08
A16: 오피스텔 | B16: =SUM(M67) -> 0 | C16: 평형 | F16: =SUM(B16*D16) -> 0 | H16: =SUM(B62) -> 0 | J16: =SUM(F16*H16) -> 0
B17: =SUM(M63) -> 0 | C17: 평형 | F17: =SUM(B17*D17) -> 0 | H17: =SUM(B63) -> 0 | J17: =SUM(F17*H17) -> 0
B18: =SUM(M64) -> 0 | C18: 평형 | F18: =SUM(B18*D18) -> 0 | H18: =SUM(B64) -> 0 | J18: =SUM(F18*H18) -> 0
B19: =SUM(M65) -> 0 | C19: 평형 | F19: =SUM(B19*D19) -> 0 | H19: =SUM(B65) -> 0 | J19: =SUM(F19*H19) -> 0
B20: 소계 | H20: =SUM(H16:I19) -> 0 | J20: =SUM(J16:K19) -> 0
A21: 근생시설 | B21: =M69 -> 201.0536 | C21: 평 | D21: 20000 | F21: =B21*D21 -> 4021072 | H21: 1 | J21: =SUM(F21) -> 4021072
B22: =M70 -> 193.8783 | C22: 평 | D22: 20000 | F22: =B22*D22 -> 3877566 | H22: 1 | J22: =SUM(F22) -> 3877566
F23: =SUM(H23*D23) -> 0 | H23: =A71 -> 0 | J23: =SUM(F23) -> 0
F24: =SUM(H24*D24) -> 0 | H24: =A72 -> 0 | J24: =SUM(F24) -> 0
B25: 소계 | H25: =SUM(H21:I24) -> 2 | J25: =SUM(J21:K24) -> 7898638
A26: 소 계 | J26: =SUM(J25,J20,J15) -> 8.7593198e+08
A27: 매출부가세 | J27: =H45 -> 783047.96
A28: 합 계 | J28: =SUM(J26:K27) -> 8.7671503e+08
A30: 2. 매출부가세 내역 | K30: 3. 공사비 과세비율(연면적기준)
A31: 지상면적 | B31: 비 율 | D31: 대지비 안분 | F31: 건물가 | H31: 부가세 | K31: 구 분 | L31: 면 적 | M31: 비 율
A32: =Q50 -> 12142.931 | B32: =A32/$A$45 -> 0.13510093 | D32: =$D$45*B32 -> 2095660.2 | F32: =J6-D32 -> 1.1684957e+08 | H32: 0 | K32: 과세면적 | L32: =R75 -> 201.0536 | M32: =L32/L34 -> 0.0022417361
A33: =Q51 -> 77342.577 | B33: =A33/$A$45 -> 0.8605051 | D33: =$D$45*B33 -> 13347993 | F33: =J7-D33 -> 7.3574012e+08 | H33: 0 | K33: 비과세면적 | L33: =S75 -> 89485.508 | M33: =L33/L34 -> 0.99775826
A34: =Q52 -> 0 | B34: =A34/$A$45 -> 0 | D34: =$D$45*B34 -> 0 | F34: =J8-D34 -> 0 | H34: 0 | K34: 면적합계 | L34: =L32+L33 -> 89686.561 | M34: =M32+M33 -> 1
A35: =Q53 -> 0 | B35: =A35/$A$45 -> 0 | D35: =$D$45*B35 -> 0 | F35: =J9-D35 -> 0 | H35: 0 | L35: =L34=Q75 -> FALSE | M35: =M34=100% -> TRUE
A36: =Q54 -> 0 | B36: =A36/$A$45 -> 0 | D36: =$D$45*B36 -> 0 | F36: =J10-D36 -> 0 | H36: =F36*0.1 -> 0
A37: =B11*H11 -> 0 | B37: =A37/$A$45 -> 0 | D37: =$D$45*B37 -> 0 | F37: =J11-D37 -> 0 | H37: =F37/11*0 -> 0
A38: =B12*H12 -> 0 | B38: =A38/$A$45 -> 0 | D38: =$D$45*B38 -> 0 | F38: =J12-D38 -> 0 | H38: =F38/11*0 -> 0
A39: =B13*H13 -> 0 | B39: =A39/$A$45 -> 0 | D39: =$D$45*B39 -> 0 | F39: =J13-D39 -> 0 | H39: =F39/11*0 -> 0
A40: =B14*H14 -> 0 | B40: =A40/$A$45 -> 0 | D40: =$D$45*B40 -> 0 | F40: =J14-D40 -> 0 | H40: =F40/11*0 -> 0
A41: =Q69 -> 201.0536 | B41: =A41/$A$45 -> 0.0022369005 | D41: =$D$45*B41 -> 34698.38 | F41: =J21-D41 -> 3986373.6 | H41: =F41*0.1 -> 398637.36 | J41: 상가
A42: =Q70 -> 193.8783 | B42: =A42/$A$45 -> 0.0021570689 | D42: =$D$45*B42 -> 33460.047 | F42: =J22-D42 -> 3844106 | H42: =F42*0.1 -> 384410.6
B43: =A43/$A$45 -> 0 | D43: =$D$45*B43 -> 0 | F43: =J23-D43 -> 0 | H43: =F43*0.1 -> 0
...

Sheet 사업수지표
A1: 경기도 화성시 장짐리 공동주택 신축사업 (Normal)
A3: 사 업 명 | G3: 경기도 화성시 장짐리 공동주택 신축사업
A4: 부지대표지번 | G4: 경기도 화성시 장짐리 228-1 일원
A5: 매입면적(토지) | G5: 105981 | M5: ㎡ | Z5: =G5*0.3025 -> 32059.252 | AI5: 평 | AJ5: 용적률 | AR5: 196.73 | AT5: % | AW5: 건폐율 | BA5: 14.55 | BK5: %
A6: 기부면적(도로등) | G6: 165 | M6: ㎡ | Z6: =G6*0.3025 -> 49.9125 | AI6: 평 | AJ6: 공사기간 | AR6: 37 | AT6: 개월 | AW6: 건축규모 | BB6: 지하 | BD6: 2 | BE6: 지상 | BG6: 24 | BI6: 20 | BK6: 동
A7: 유휴면적(토지) | G7: 0 | M7: ㎡ | Z7: =G7*0.3025 -> 0 | AI7: 평 | AJ7: 세대수 | AR7: 1885 | AT7: 세대 | AW7: equity | BA7: =AR89 -> 6585203
A8: 사업면적(토지) | G8: =G5-G6-G7 -> 105816 | M8: ㎡ | Z8: =G8*0.3025 -> 32009.34 | AI8: 평 | AJ8: 주차대수 | AR8: 2529 | AT8: 대 | AW8: 공사비선급금
A9: 전체연면적(건물) | G9: =SUM(G10,AR10) -> 297049.16 | M9: ㎡ | Z9: =G9*0.3025 -> 89857.371 | AI9: 평 | AJ9: 지하연면적(건물) | AR9: =AR10*0.3025 -> 26785.7 | AT9: 평 | AW9: 대여금
A10: 지상연면적(건물) | G10: 208501.39 | M10: ㎡ | Z10: =G10*0.3025 -> 63071.67 | AI10: 평 | AJ10: 지하연면적(건물) | AR10: 88547.77 | AT10: ㎡ | AW10: 신탁최대차입금 | BA10: =현금흐름표!BY129 -> 3082966.2 | BM10: (단위:천원) | CA10: 부가세미포함
A11: 구 분 | N11: 시행사 금액 | T11: 시공사 금액 | Z11: 금액 | AR11: 신탁 전 투입(vat포함) | AT11: 신탁후 | AU11: 분양불사업비 | AV11: 정산사업비 | AW11: 산출 내역 | BM11: 비 고 | BT11: 비율 | BW11: 발코니포함 | CA11: 발코니포함
N12: VAT별도 | T12: VAT별도 | Z12: 공급가액 | AF12: 부가세 | AL12: 총액 | AR12: Equity | AS12: PF | AT12: 계정대 | BM12: 분양가 | BS12: VAT포함
A13: 수입 | B13: 아파트 | G13: 타입 | I13: 59A | Z13: =AW13*BB13*BH13 -> 1.1894523e+08 | AF13: 0 | AL13: =Z13+AF13 -> 1.1894523e+08 | AW13: =분양개요!B6 -> 25.285975 | AZ13: 평 | BA13: × | BB13: =분양개요!D6 -> 14000 | BE13: 천원 | BG13: × | BH13: =분양개요!B50 -> 336 | BK13: 세대 | BM13: 세대당 | BP13: =Z13/BH13 -> 354003.65 | BR13: 천원 | BS13: 좌동 | BT13: =AL13/$AL$23 -> 0.12970004 | BW13: =BP13+$BB$22 -> 374003.65 | BY13: =BW13/AW13 -> 14790.952
G14: 타입 | I14: 84A | Z14: =AW14*BB14*BH14 -> 7.4908811e+08 | AF14: 0 | AL14: =Z14+AF14 -> 7.4908811e+08 | AW14: =분양개요!B7 -> 34.542475 | AZ14: 평 | BA14: × | BB14: =분양개요!D7 -> 14000 | BE14: 천원 | BG14: × | BH14: =분양개요!B51 -> 1549 | BK14: 세대 | BM14: 세대당 | BP14: =Z14/BH14 -> 483594.65 | BR14: 천원 | BS14: 좌동 | BT14: =AL14/$AL$23 -> 0.81681932 | BW14: =BP14+$BB$22 -> 503594.65 | BY14: =BW14/AW14 -> 14578.997
G15: 타입 | I15: 84B | Z15: =AW15*BB15*BH15 -> 0 | AF15: 0 | AL15: =Z15+AF15 -> 0 | AW15: =분양개요!B8 -> 0 | AZ15: 평 | BA15: × | BB15: =분양개요!D8 -> 0 | BE15: 천원 | BG15: × | BH15: =분양개요!B52 -> 0 | BK15: 세대 | BM15: 세대당 | BP15: =Z15/BH15 -> #DIV/0! | BR15: 천원 | BS15: 좌동 | BT15: =AL15/$AL$23 -> 0 | BW15: =BP15+$BB$22 -> #DIV/0! | BY15: =BW15/AW15 -> #DIV/0!
G16: 타입 | I16: 84C | Z16: =AW16*BB16*BH16 -> 0 | AF16: 0 | AL16: =Z16+AF16 -> 0 | AW16: =분양개요!B9 -> 0 | AZ16: 평 | BA16: × | BB16: =분양개요!D9 -> 0 | BE16: 천원 | BG16: × | BH16: =분양개요!B53 -> 0 | BK16: 세대 | BM16: 세대당 | BP16: =Z16/BH16 -> #DIV/0! | BR16: 천원 | BS16: 좌동 | BT16: =AL16/$AL$23 -> 0 | BW16: =BP16+$BB$22 -> #DIV/0! | BY16: =BW16/AW16 -> #DIV/0!
G17: 타입 | I17: 117A | Z17: =AW17*BB17*BH17 -> 0 | AF17: =분양개요!H36 -> 0 | AL17: =Z17+AF17 -> 0 | AW17: =분양개요!B10 -> 0 | AZ17: 평 | BA17: × | BB17: =분양개요!D10 -> 0 | BE17: 천원 | BG17: × | BH17: =분양개요!B54 -> 0 | BK17: 세대 | BM17: 세대당 | BP17: =Z17/BH17 -> #DIV/0! | BR17: 천원 | BS17: =AL17/BH17 -> #DIV/0! | BT17: =AL17/$AL$23 -> 0 | BW17: =BS17+BB22 -> #DIV/0! | BY17: =BW17/AW17 -> #DIV/0! | CA17: =BP17+BB22 -> #DIV/0! | CB17: =CA17/AW17 -> #DIV/0!
G18: 소계 | Z18: =SUM(Z13:AE17) -> 8.6803334e+08 | AF18: =SUM(AF13:AK17) -> 0 | AL18: =Z18+AF18 -> 8.6803334e+08 | AW18: =분양개요!I59 -> 62002.381 | AZ18: 평 | BA18: × | BB18: =Z18/AW18 -> 14000 | BE18: 천원 | BG18: | | BH18: =SUM(BH13:BJ17) -> 1885 | BK18: 세대 | BT18: =AL18/$AL$23 -> 0.94651937 | BV18: =Z18/$Z$23 -> 0.95109995
B19: 근생 | G19: 타입 | I19: 1층 | Z19: =AW19*BB19*BH19 -> 4021072 | AF19: 378594 | AL19: =Z19+AF19 -> 4399666 | AW19: =분양개요!B21 -> 201.0536 | AZ19: 평 | BA19: × | BB19: =분양개요!D21 -> 20000 | BE19: 천원 | BG19: × | BH19: 1 | BK19: 세대 | BM19: 세대당 | BP19: =Z19/BH19 -> 4021072 | BR19: 천원 | BS19: =AL19 -> 4399666 | BT19: =AL19/$AL$23 -> 0.004797476 | BV19: =Z19/$Z$23 -> 0.0044058692 | CA19: 부가세 과세
G20: 타입 | I20: 지하1층 | Z20: =AW20*BB20*BH20 -> 2908174.5 | AF20: 268144 | AL20: =Z20+AF20 -> 3176318.5 | AW20: =분양개요!B22 -> 193.8783 | AZ20: 평 | BA20: × | BB20: 15000 | BE20: 천원 | BG20: × | BH20: 1 | BK20: 세대 | BM20: 세대당 | BP20: =Z20/BH20 -> 2908174.5 | BR20: 천원 | BS20: =AL20 -> 3176318.5 | BT20: =AL20/$AL$23 -> 0.0034635156 | BV20: =Z20/$Z$23 -> 0.0031864728 | CA20: 공사성 | CB20: =분양개요!M32 -> 0.0022417361
G21: 소계 | Z21: =SUM(Z19:AE20) -> 6929246.5 | AF21: =SUM(AF19:AK20) -> 646738 | AL21: =SUM(AL19:AQ20) -> 7575984.5 | AW21: =분양개요!M73 -> 394.9319 | AZ21: 평 | BA21: × | BB21: =Z21/AW21 -> 17545.421 | BE21: 천원 | BG21: | | BH21: =SUM(BH19:BJ20) -> 2 | BK21: 세대 | BT21: =AL21/$AL$23 -> 0.0082609915 | BV21: =Z21/$Z$23 -> 0.007592342 | CA21: 사업성 | CB21: =CB20*CC21 -> 0.0017933889 | CC21: 0.8
B22: 발코니 확장비 | Z22: =BB22*BH22 -> 37700000 | AF22: =Z22*0.1 -> 3770000 | AL22: =SUM(Z22:AK22) -> 41470000 | BB22: 20000 | BE22: 천원/세대 | BG22: | | BH22: =BH18 -> 1885 | BK22: 세대 | BT22: =AL22/$AL$23 -> 0.045219643 | BV22: =Z22/$Z$23 -> 0.041307708 | CA22: 과세비율 | CC22: 부가세 | CD22: 면세분 | CE22: 과세분
B23: 매출합계 | N23: =#REF!+#REF!+#REF! -> #REF! | T23: =#REF!+#REF!+#REF! -> #REF! | Z23: =SUM(Z18,Z21,Z22) -> 9.1266259e+08 | AF23: =SUM(AF18,AF21,AF22) -> 4416738 | AL23: =SUM(AL18,AL21,AL22) -> 9.1707932e+08 | BT23: =SUM(BT18,BT21:BU22) -> 1 | BV23: =Z23/$Z$23 -> 1 | CA23: 1. 매출부가세 | CC23: =AF23 -> 4416738 | CD23: =CC23-CE23 -> 0 | CE23: =CC23 -> 4416738
A24: 비용 | B24: 토지비 | G24: 채권매입비용 | N24: 11500000 | T24: 11500000 | Z24: 96000000 | AF24: 0 | AL24: =Z24+AF24 -> 96000000 | AR24: 0 | AS24: 96000000 | AT24: =AL24-AR24-AS24 -> 0 | AU24: 0 | AV24: 0 | BM24: 군인공제회(매몰비용) | BT24: =AL24/$AL$23 -> 0.10468015 | BV24: =Z24/$Z$23 -> 0.10518674 | BY24: =G24 -> 채권매입비용 | CB24: =IF($CA24=$CA$21, $CB$21, IF($CA24=$CA$20,$CB$20, )) -> 0 | CC24: =AF24 -> 0 | CD24: =CC24-CE24 -> 0 | CE24: =CC24*CB24 -> 0
G25: 토지비(공동주택) | N25: 575000 | T25: =Z25 -> 13969158 | Z25: 13969158 | AL25: =Z25+AF25 -> 13969158 | AR25: 0 | AS25: =AL25 -> 13969158 | AT25: =AL25-AR25-AS25 -> 0 | AU25: 0 | AV25: 0 | BM25: 미매입부지(공동주택) | BT25: =AL25/$AL$23 -> 0.015232224 | BV25: =Z25/$Z$23 -> 0.015305939 | BY25: =G25 -> 토지비(공동주택) | CA25: 사업성 | CB25: =IF($CA25=$CA$21, $CB$21, IF($CA25=$CA$20,$CB$20, )) -> 0.0017933889 | CC25: =AF25 -> 0 | CD25: =CC25-CE25 -> 0 | CE25: =CC25*CB25 -> 0
G26: 토지비(기반시설부지) | Z26: 11960903 | AL26: =Z26+AF26 -> 11960903 | AR26: 0 | AS26: 11960903 | AT26: =AL26-AR26-AS26 -> 0 | AU26: 0 | AV26: 0 | BM26: 미매입부지(기반시설부지) | BT26: =AL26/$AL$23 -> 0.013042387 | BV26: =Z26/$Z$23 -> 0.013105504
G27: 토지비(211,222-2번지) | Z27: 7470960 | AL27: =Z27+AF27 -> 7470960 | AR27: 0 | AS27: =AL27 -> 7470960 | AT27: =AL27-AR27-AS27 -> 0 | AU27: 0 | AV27: 0 | BM27: 엠에스홀딩스 (7,470,960 토지매입비) | BT27: =AL27/$AL$23 -> 0.0081464709 | BV27: =Z27/$Z$23 -> 0.0081858949 | BW27: =AS27-5000000 -> 2470960
G28: 취등록세 | N28: 575000 | T28: =Z28 -> 1603249 | Z28: =AW28*BC28 -> 1603249 | AL28: =Z28+AF28 -> 1603249 | AR28: 0 | AS28: =(AS25+AS26+AS27)*BC28 -> 1603249 | AT28: 0 | AU28: 0 | AV28: 0 | AW28: =AS25+AS26+AS27 -> 33401021 | BA28: 천원 | BB28: × | BC28: 0.048 | BM28: 미매입부지(공동주택+기반시설부지+엠에스 토지) | BT28: =AL28/$AL$23 -> 0.0017482119 | BV28: =Z28/$Z$23 -> 0.0017566722 | BY28: =G28 -> 취등록세 | CA28: 사업성 | CB28: =IF($CA28=$CA$21, $CB$21, IF($CA28=$CA$20,$CB$20, )) -> 0.0017933889 | CC28: =AF28 -> 0 | CD28: =CC28-CE28 -> 0 | CE28: =CC28*CB28 -> 0
G29: 명도 및 보상비 | N29: 575000 | T29: =Z29 -> 3882030.6 | Z29: =AW29*BC29 -> 3882030.6 | AF29: 0 | AL29: =Z29+AF29 -> 3882030.6 | AR29: 0 | AS29: =AL29-AR29 -> 3882030.6 | AT29: =AL29-AR29-AS29 -> 0 | AU29: 0 | AV29: 0 | AW29: =Z24+Z25+Z26+Z27 -> 129401021 | BA29: 천원 | BB29: × | BC29: 0.03 | BT29: =AL29/$AL$23 -> 0.0042330369 | BV29: =Z29/$Z$23 -> 0.0042535223 | BY29: =G29 -> 명도 및 보상비 | CB29: =IF($CA29=$CA$21, $CB$21, IF($CA29=$CA$20,$CB$20, )) -> 0 | CC29: =AF29 -> 0 | CD29: =CC29-CE29 -> 0 | CE29: =CC29*CB29 -> 0
G30: 주식근질권해제비용 | Z30: 5000000 | AF30: 0 | AL30: =Z30+AF30 -> 5000000 | AR30: 0 | AS30: =AL30-AR30 -> 5000000 | BT30: =AL30/$AL$23 -> 0.0054520911 | BV30: =Z30/$Z$23 -> 0.0054784759
G31: 인허가 비용 | Z31: 5444723 | AF31: 0 | AL31: =Z31+AF31 -> 5444723 | AR31: 5444723 | AS31: =AL31-AR31 -> 0 | BM31: 농지보전부담금, 개발행위 이행보증금, 산지복구비 등 | BT31: =AL31/$AL$23 -> 0.0059370251 | BV31: =Z31/$Z$23 -> 0.0059657568
G32: 소계 | N32: =SUM(N24:S28) -> 12650000 | T32: =SUM(T24:Y28) -> 27072407 | Z32: =SUM(Z24:AE31) -> 1.4533102e+08 | AF32: =SUM(AF24:AK29) -> 0 | AL32: =SUM(AL24:AQ31) -> 1.4533102e+08 | AR32: =SUM(AR24:AR31) -> 5444723 | AS32: =SUM(AS24:AS31) -> 1.398863e+08 | AT32: =SUM(AT24:AT28) -> 0 | AU32: =SUM(AU24:AU31) -> 0 | AV32: =SUM(AV24:AV31) -> 0 | BT32: =AL32/$AL$23 -> 0.1584716 | BV32: =Z32/$Z$23 -> 0.1592385 | CC32: =SUM(CC24:CC28)=AF32 -> TRUE | CE32: =CC32*CB32 -> 0
B33: 건축비 | G33: 직접공사비(본공사) | N33: 94609110 | T33: =AW33*4200 -> 3.7740096e+08 | Z33: =AW33*BC33 -> 4.4030112e+08 | AF33: =Z33*분양개요!M32*0.1 -> 98703.89 | AL33: =Z33+AF33 -> 4.4039982e+08 | AT33: =AL33*90% -> 3.9635984e+08 | AV33: =AL33-AT33 -> 44039982 | AW33: =+Z9 -> 89857.371 | BA33: 평 | BB33: × | BC33: 4900 | BF33: 천원 | BM33: 서한 시공참여의향서 공사비 4,800천원(파일공사 제외,VAT제외) | BT33: =AL33/$AL$23 -> 0.48021999 | BV33: =Z33/$Z$23 -> 0.48243581 | BY33: =G33 -> 직접공사비(본공사) | CA33: 공사성 | CB33: =IF($CA33=$CA$21, $CB$21, IF($CA33=$CA$20,$CB$20, )) -> 0.0022417361 | CC33: =AF33 -> 98703.89 | CD33: =CC33-CE33 -> 98482.622 | CE33: =CC33*CB33 -> 221.26807
G34: 기타공사비(본공사) | BA34: 평 | BB34: × | BF34: 천원 | BT34: =AL34/$AL$23 -> 0 | BV34: =Z34/$Z$23 -> 0 | BY34: =G34 -> 기타공사비(본공사) | CA34: 공사성 | CB34: =IF($CA34=$CA$21, $CB$21, IF($CA34=$CA$20,$CB$20, )) -> 0.0022417361
G35: 각종인입비 | N35: 692261 | T35: =Z35 -> 2695721.1 | Z35: =AW35*BC35 -> 2695721.1 | AF35: =Z35*0.1 -> 269572.11 | AL35: =Z35+AF35 -> 2965293.2 | AT35: =AL35-AR35-AS35 -> 2965293.2 | AW35: =+Z9 -> 89857.371 | BA35: 평 | BB35: × | BC35: 30 | BF35: 천원 | BT35: =AL35/$AL$23 -> 0.0032334098 | BV35: =Z35/$Z$23 -> 0.0029536887 | BY35: =G35 -> 각종인입비 | CA35: 공사성 | CB35: =IF($CA35=$CA$21, $CB$21, IF($CA35=$CA$20,$CB$20, )) -> 0.0022417361 | CC35: =AF35 -> 269572.11 | CD35: =CC35-CE35 -> 268967.8 | CE35: =CC35*CB35 -> 604.30953
G36: 조건부이행공사비 | N36: 300000 | T36: 300000 | Z36: =AW36*BC36 -> 6401868 | AF36: =Z36*0.1 -> 640186.8 | AL36: =Z36+AF36 -> 7042054.8 | AT36: =AL36-AR36-AS36 -> 7042054.8 | AW36: =Z8 -> 32009.34 | BA36: 평 | BB36: × | BC36: 200 | BF36: 천원 | BT36: =AL36/$AL$23 -> 0.0076787848 | BV36: =Z36/$Z$23 -> 0.0070144959 | BY36: =G36 -> 조건부이행공사비 | CA36: 공사성 | CB36: =IF($CA36=$CA$21, $CB$21, IF($CA36=$CA$20,$CB$20, )) -> 0.0022417361 | CC36: =AF36 -> 640186.8 | CD36: =CC36-CE36 -> 638751.67 | CE36: =CC36*CB36 -> 1435.1298
G37: 예술장식품비 | N37: 300000 | T37: 300000 | Z37: =AW37*BC37*BI37 -> 685589.06 | AF37: =Z37*0.1 -> 68558.906 | AL37: =Z37+AF37 -> 754147.96 | AS37: 0 | AT37: =AL37-AR37-AS37 -> 754147.96 | AW37: =Z10 -> 63071.67 | BA37: 평 | BB37: × | BC37: 2174 | BF37: 천원 | BH37: × | BI37: 0.005 | BT37: =AL37/$AL$23 -> 0.00082233668 | BV37: =Z37/$Z$23 -> 0.00075119663 | BY37: =G37 -> 예술장식품비 | CA37: 공사성 | CB37: =IF($CA37=$CA$21, $CB$21, IF($CA37=$CA$20,$CB$20, )) -> 0.0022417361 | CC37: =AF37 -> 68558.906 | CD37: =CC37-CE37 -> 68405.215 | CE37: =CC37*CB37 -> 153.69097
G38: 소계 | N38: =SUM(N33:S36) -> 95601371 | T38: =SUM(T33:Y36) -> 3.8039668e+08 | Z38: =SUM(Z33:AE37) -> 4.500843e+08 | AF38: =SUM(AF33:AK37) -> 1077021.7 | AL38: =SUM(AL33:AQ37) -> 4.5116132e+08 | AR38: =SUM(AR33:AR37) -> 0 | AS38: =SUM(AS33:AS37) -> 0 | AT38: =SUM(AT33:AT37) -> 4.0712134e+08 | AU38: =SUM(AU33:AU37) -> 0 | AV38: =SUM(AV33:AV37) -> 44039982 | BT38: =AL38/$AL$23 -> 0.49195452 | BV38: =Z38/$Z$23 -> 0.4931552 | CC38: =SUM(CC33:CC37)=AF38 -> TRUE
B39: 용역비 | G39: 설계비 | N39: 1450000 | T39: 1450000 | Z39: 4368000 | AF39: =Z39*10% -> 436800 | AL39: =Z39+AF39 -> 4804800 | AR39: =AL39*10% -> 480480 | AS39: 0 | AT39: =AL39-AR39-AS39 -> 4324320 | AW39: =+Z9 -> 89857.371 | BA39: 평 | BB39: × | BC39: 80 | BF39: 천원 | BT39: =AL39/$AL$23 -> 0.0052392414 | BV39: =Z39/$Z$23 -> 0.0047859966 | BY39: =G39 -> 설계비 | CA39: 공사성 | CB39: =IF($CA39=$CA$21, $CB$21, IF($CA39=$CA$20,$CB$20, )) -> 0.0022417361 | CC39: =AF39 -> 436800 | CD39: =CC39-CE39 -> 435820.81 | CE39: =CC39*CB39 -> 979.19032
G40: 감리비 | N40: 2538293 | T40: =Z40 -> 9884310.8 | Z40: =AW40*BC40 -> 9884310.8 | AF40: =Z40*0.1 -> 988431.08 | AL40: =Z40+AF40 -> 10872742 | AS40: =현금흐름표!Y60 -> 0 | AT40: =AL40-AU40 -> 9785467.7 | AU40: =AL40*10% -> 1087274.2 | AW40: =+Z9 -> 89857.371 | BA40: 평 | BB40: × | BC40: 110 | BF40: 천원 | BT40: =AL40/$AL$23 -> 0.011855836 | BV40: =Z40/$Z$23 -> 0.010830192 | BY40: =G40 -> 감리비 | CA40: 공사성 | CB40: =IF($CA40=$CA$21, $CB$21, IF($CA40=$CA$20,$CB$20, )) -> 0.0022417361 | CC40: =AF40 -> 988431.08 | CD40: =CC40-CE40 -> 986215.28 | CE40: =CC40*CB40 -> 2215.8016
G41: 미매입 토지 용역비 | N41: 96941 | T41: =Z41 -> 0 | AS41: 0 | AT41: =AL41-AR41-AS41 -> 0 | BT41: =AL41/$AL$23 -> 0 | BV41: =Z41/$Z$23 -> 0 | BY41: =G41 -> 미매입 토지 용역비 | CA41: 공사성 | CB41: =IF($CA41=$CA$21, $CB$21, IF($CA41=$CA$20,$CB$20, )) -> 0.0022417361 | CC41: =AF41 -> 0 | CD41: =CC41-CE41 -> 0 | CE41: =CC41*CB41 -> 0
...

Sheet 현금흐름표
A1: ● 자금계획 (Cash Flow) 안 | N1: PF대출기간 | AB1: 1 | AC1: 2 | AD1: 3 | AE1: 4 | AF1: 5 | AG1: 6 | AH1: 7 | AI1: 8 | AJ1: 9 | AK1: 10 | AL1: 11 | AM1: 12 | AN1: 13 | AO1: 14 | AP1: 15 | AQ1: 16 | AR1: 17 | AS1: 18 | AT1: 19 | AU1: 20 | AV1: 21 | AW1: 22 | AX1: 23 | AY1: 24 | AZ1: 25 | BA1: 26 | BB1: 27 | BC1: 28 | BD1: 29 | BE1: 30 | BF1: 31 | BG1: 32 | BH1: 33 | BI1: 34 | BJ1: 35 | BK1: 36 | BL1: 37 | BM1: 38 | BN1: 39 | CC1: 3 | CD1: 4 | CE1: 5 | CF1: 6 | CG1: 7 | CH1: 8 | CI1: 9 | CJ1: 10 | CK1: 11 | CL1: 12 | CM1: 13 | CN1: 14 | CO1: 15 | CP1: 16 | CQ1: 17 | CR1: 18 | CS1: 19 | CT1: 20 | CU1: 21 | CV1: 22 | CW1: 23 | CX1: 24 | CY1: 25 | CZ1: 26 | DA1: 27 | DB1: 28 | DC1: 29 | DD1: 30 | DE1: 31 | DF1: 32 | DG1: 33 | DH1: 34 | DI1: 35 | DJ1: 36 | DK1: 37 | DL1: 38 | DM1: 39 | DN1: 40 | DO1: 41 | DP1: 42 | DQ1: 43 | DR1: 44 | DS1: 45 | DT1: 46 | DU1: 47 | DV1: 48 | DW1: 49 | DX1: 50 | DY1: 51 | DZ1: 52
A2: ● 사업명 : | B2: =+사업수지표!G3 -> 경기도 화성시 장짐리 공동주택 신축사업 | N2: 50 | O2: 개월 | Q2: 1 | R2: 2 | S2: 3 | T2: 4 | U2: 5 | V2: 6 | W2: 7 | X2: 8 | Y2: 9 | Z2: 10 | AA2: 11 | AB2: 12 | AC2: 13 | AD2: 14 | AE2: 15 | AF2: 16 | AG2: 17 | AH2: 18 | AI2: 19 | AJ2: 20 | AK2: 21 | AL2: 22 | AM2: 23 | AN2: 24 | AO2: 25 | AP2: 26 | AQ2: 27 | AR2: 28 | AS2: 29 | AT2: 30 | AU2: 31 | AV2: 32 | AW2: 33 | AX2: 34 | AY2: 35 | AZ2: 36 | BA2: 37 | BB2: 38 | BC2: 39 | BD2: 40 | BE2: 41 | BF2: 42 | BG2: 43 | BH2: 44 | BI2: 45 | BJ2: 46 | BK2: 47 | BL2: 48 | BM2: 49 | BN2: 50 | BO2: 51 | BP2: 52
A3: ● 공 기 : | B3: 37 | E3: 개월 | Q3: 1 | R3: 2 | S3: 3 | T3: 4 | U3: 5 | V3: 6 | W3: 7 | X3: 8 | Y3: 9 | Z3: 10 | AJ3: 신탁차입이자율 | AK3: =사업수지표!BD75 -> 0.0777 | AL3: PF수수료 | AM3: =사업수지표!BD80 -> 0 | AN3: 무이자 비중 | AP3: 무이자 이자율 | AQ3: =사업수지표!BD76 -> 0.042
A4: 내용(일정) | N4: 합계 | O4: 기집행 | P4: 신탁계약/PF | Q4: 준비 | R4: 준비 | S4: 준비 | T4: 준비 | U4: 준비 | V4: 준비 | W4: 준비 | X4: 준비 | Y4: 준비 | Z4: 준비 | AA4: 착공/분양 | AG4: 중도금1차 | AM4: 중도금2차 | AS4: 중도금3차 | AY4: 중도금4차 | BE4: 중도금 5차 | BI4: 중도금 6차 | BL4: 준공/입주 | BN4: 정산 | BY4: 합계
A5: 구 분 | Q5: D-10 | R5: D-9 | S5: D-8 | T5: D-7 | U5: D-6 | V5: D-5 | W5: D-4 | X5: D-3 | Y5: D-2 | Z5: D-1 | AA5: D | AB5: D+1 | AC5: D+2 | AD5: D+3 | AE5: D+4 | AF5: D+5 | AG5: D+6 | AH5: D+7 | AI5: D+8 | AJ5: D+9 | AK5: D+10 | AL5: D+11 | AM5: D+12 | AN5: D+13 | AO5: D+14 | AP5: D+15 | AQ5: D+16 | AR5: D+17 | AS5: D+18 | AT5: D+19 | AU5: D+20 | AV5: D+21 | AW5: D+22 | AX5: D+23 | AY5: D+24 | AZ5: D+25 | BA5: D+26 | BB5: D+27 | BC5: D+28 | BD5: D+29 | BE5: D+30 | BF5: D+31 | BG5: D+32 | BH5: D+33 | BI5: D+34 | BJ5: D+35 | BK5: D+36 | BL5: D+37 | BM5: 33 | BN5: 34 | BO5: 35 | BP5: 36 | BQ5: 37 | BR5: 38 | BS5: 39 | BT5: 40 | BU5: 41 | BV5: 40 | BW5: 41 | BX5: 42
A6: 시 기 | P6: 46082 | Q6: 46113 | R6: 46143 | S6: 46174 | T6: 46204 | U6: 46235 | V6: 46266 | W6: 46296 | X6: 46327 | Y6: 46357 | Z6: 46388 | AA6: 46419 | AB6: 46447 | AC6: 46478 | AD6: 46508 | AE6: 46539 | AF6: 46569 | AG6: 46600 | AH6: 46631 | AI6: 46661 | AJ6: 46692 | AK6: 46722 | AL6: 46753 | AM6: 46784 | AN6: 46813 | AO6: 46844 | AP6: 46874 | AQ6: 46905 | AR6: 46935 | AS6: 46966 | AT6: 46997 | AU6: 47027 | AV6: 47058 | AW6: 47088 | AX6: 47119 | AY6: 47150 | AZ6: 47178 | BA6: 47209 | BB6: 47239 | BC6: 47270 | BD6: 47300 | BE6: 47331 | BF6: 47362 | BG6: 47392 | BH6: 47423 | BI6: 47453 | BJ6: 47484 | BK6: 47515 | BL6: 47543 | BM6: 47574 | BN6: 47604 | BO6: 47635 | BP6: 47665 | BQ6: 47270 | BR6: 47300 | BS6: 47331 | BT6: 47362 | BU6: 47392 | BV6: 47423 | BW6: 47453 | BX6: =BW6+31 -> 47484
A7: 공정율 | B7: 공정율 | G7: 월계 | AA7: =공정률!F4 -> 0.0096 | AB7: =공정률!G4 -> 0.0096 | AC7: =공정률!H4 -> 0.0116 | AD7: =공정률!I4 -> 0.0116 | AE7: =공정률!J4 -> 0.0136 | AF7: =공정률!K4 -> 0.0136 | AG7: =공정률!L4 -> 0.0186 | AH7: =공정률!M4 -> 0.0186 | ... BL7: =공정률!AQ4 -> 0 | BY7: =SUM(P7:BS7) -> 1
G8: 누계 | N8: =+BY8 -> 1 | P8: 0 | X8: 0 | Y8: =X8+Y7 -> 0 | AA8: =AA7 -> 0.0096 | AB8: =AA8+AB7 -> 0.0192 | AC8: =AB8+AC7 -> 0.0308 | AD8: =AC8+AD7 -> 0.0424 | AE8: =AD8+AE7 -> 0.056 | AF8: =AE8+AF7 -> 0.0696 | AG8: =AF8+AG7 -> 0.0882 | AH8: =AG8+AH7 -> 0.1068 | AI8: =AH8+AI7 -> 0.1284 | ... BN8: =BM8+BN7 -> 1 | BO8: =BM8+BO7 -> 1 | BP8: =BO8+BP7 -> 1 | BQ8: =BP8+BQ7 -> 1 | BR8: =BQ8+BR7 -> 1 | BS8: =BR8+BS7 -> 1 | BT8: =BS8+BT7 -> 1 | BU8: =BT8+BU7 -> 1 | BV8: =BU8+BV7 -> 1 | BW8: =BV8+BW7 -> 1 | BX8: =BW8+BX7 -> 1 | BY8: =BX8 -> 1
A9: 분양률 | B9: =[28]사업수지표!B15 -> 아파트 | G9: 월별 | AA9: 0.2 | AB9: 0.1 | AC9: 0.05 | AD9: 0.05 | AE9: 0.1 | AF9: 0.03 | AG9: 0.02 | AH9: 0.04 | AI9: 0.03 | AJ9: 0.05 | AK9: 0.05 | AL9: 0.03 | AM9: 0.03 | AN9: 0.04 | AO9: 0.04 | AP9: 0.03 | AQ9: 0.03 | AR9: 0.01 | AS9: 0.01 | AT9: 0.01 | AU9: 0.01 | AV9: 0.01 | AW9: 0.01 | AX9: 0.01 | AY9: 0 | BI9: 0.01 | BY9: =SUM(P9:BS9) -> 1
G10: 누계 | N10: 1 | X10: =+P10+X9 -> 0 | Y10: =+X10+Y9 -> 0 | AA10: =X10+AA9 -> 0.2 | AB10: =AA10+AB9 -> 0.3 | AC10: =AB10+AC9 -> 0.35 | AD10: =AC10+AD9 -> 0.4 | AE10: =AD10+AE9 -> 0.5 | AF10: =AE10+AF9 -> 0.53 | AG10: =AF10+AG9 -> 0.55 | AH10: =AG10+AH9 -> 0.59 | AI10: =AH10+AI9 -> 0.62 | ... BX10: =BW10+BX9 -> 1 | BY10: =BX10 -> 1
A11: 분양률 | B11: =[28]사업수지표!#REF! -> #REF! | G11: 월별 | AL11: =VLOOKUP($N$1,#REF!,CQ1,FALSE) -> #REF! | AQ11: =VLOOKUP($N$1,#REF!,CR1,FALSE) -> #REF! | AR11: =VLOOKUP($N$1,#REF!,CS1,FALSE) -> #REF! | AS11: =VLOOKUP($N$1,#REF!,CT1,FALSE) -> #REF! | AT11: =VLOOKUP($N$1,#REF!,CU1,FALSE) -> #REF! | AU11: =VLOOKUP($N$1,#REF!,CV1,FALSE) -> #REF! | AV11: =VLOOKUP($N$1,#REF!,CW1,FALSE) -> #REF! | AW11: =VLOOKUP($N$1,#REF!,CX1,FALSE) -> #REF! | AX11: =VLOOKUP($N$1,#REF!,CY1,FALSE) -> #REF! | ... BN11: =VLOOKUP($N$1,#REF!,DO1,FALSE) -> #REF! | BO11: =VLOOKUP($N$1,#REF!,DO1,FALSE) -> #REF! | BP11: =VLOOKUP($N$1,#REF!,DP1,FALSE) -> #REF!
G12: 누계 | N12: 1 | X12: =+P12+X11 -> 0 | Y12: =+X12+Y11 -> 0 | AL12: =AL11 -> #REF! | AQ12: =+AL12+AQ11 -> #REF! | AR12: =+AQ12+AR11 -> #REF! | AS12: =+AR12+AS11 -> #REF! | AT12: =+AS12+AT11 -> #REF! | AU12: =+AT12+AU11 -> #REF! | AV12: =+AU12+AV11 -> #REF! | AW12: =+AV12+AW11 -> #REF! | AX12: =+AW12+AX11 -> #REF! | AY12: =+AX12+AY11 -> #REF! | ... BN12: =+BM12+BN11 -> #REF! | BO12: =+BM12+BO11 -> #REF! | BP12: =+BO12+BP11 -> #REF!
A13: 분양률 | B13: =[28]사업수지표!B23 -> 상가 | G13: 월별 | AQ13: 0.2 | AR13: 0.05 | AS13: 0.05 | AT13: 0.05 | AU13: 0.05 | AV13: 0.05 | AW13: 0.05 | AX13: 0.05 | AY13: 0.1 | AZ13: 0.05 | BA13: 0.05 | BB13: 0.05 | BC13: 0.05 | BD13: 0.05 | BF13: 0.05 | BH13: 0.05 | BY13: =SUM(P13:BR13) -> 1
G14: 누계 | N14: 1 | X14: =+P14+X13 -> 0 | Y14: =+X14+Y13 -> 0 | AK14: =SUM(AK13,AJ14) -> 0 | AL14: =SUM(AL13,AK14) -> 0 | AM14: =SUM(AM13,AL14) -> 0 | AP14: =SUM(AP13,AL14) -> 0 | AQ14: =SUM(AQ13,AP14) -> 0.2 | AR14: =SUM(AR13,AQ14) -> 0.25 | AS14: =SUM(AS13,AR14) -> 0.3 | AT14: =SUM(AT13,AS14) -> 0.35 | AU14: =SUM(AU13,AT14) -> 0.4 | AV14: =SUM(AV13,AU14) -> 0.45 | AW14: =SUM(AW13,AV14) -> 0.5 | AX14: =SUM(AX13,AW14) -> 0.55 | ... BN14: =SUM(BN13,BM14) -> 1 | BO14: =SUM(BO13,BM14) -> 1 | BP14: =SUM(BP13,BO14) -> 1 | BQ14: =SUM(BQ13,BP14) -> 1 | BR14: =SUM(BR13,BQ14) -> 1 | BS14: =SUM(BS13,BR14) -> 1 | BT14: =SUM(BT13,BS14) -> 1 | BU14: =SUM(BU13,BT14) -> 1 | BV14: =SUM(BV13,BU14) -> 1 | BW14: =SUM(BW13,BV14) -> 1 | BX14: =SUM(BX13,BW14) -> 1 | BY14: =BX14 -> 1
A15: 수입 | B15: =B9 -> 아파트 | G15: 계약금 | K15: 0.1 | N15: =K15*$N$23 -> 86803334 | AA15: =AA9*$N$15 -> 17360667 | AB15: =AB9*$N$15 -> 8680333.4 | AC15: =AC9*$N$15 -> 4340166.7 | AD15: =AD9*$N$15 -> 4340166.7 | AE15: =AE9*$N$15 -> 8680333.4 | AF15: =AF9*$N$15 -> 2604100 | AG15: =AG9*$N$15 -> 1736066.7 | AH15: =AH9*$N$15 -> 3472133.4 | ... BX15: =BX9*$N$15 -> 0 | BY15: =SUM(P15:BO15) -> 86803334 | BZ15: =BY15-N15 -> 0
G16: 1차중도금 | K16: 0.1 | N16: =K16*$N$23 -> 86803334 | AG16: =AG10*$N$16 -> 47741834 | AH16: =$N$16*AH9 -> 3472133.4 | AI16: =$N$16*AI9 -> 2604100 | AJ16: =$N$16*AJ9 -> 4340166.7 | AK16: =$N$16*AK9 -> 4340166.7 | AL16: =$N$16*AL9 -> 2604100 | AM16: =$N$16*AM9 -> 2604100 | AN16: =$N$16*AN9 -> 3472133.4 | AO16: =$N$16*AO9 -> 3472133.4 | ... BP16: =$N$16*BP9 -> 0 | BQ16: =BQ9*$N$16 -> 0 | BR16: =BR9*$N$16 -> 0 | BS16: =BS9*$N$16 -> 0 | BT16: =BT9*$N$16 -> 0 | BU16: =BU9*$N$16 -> 0 | BV16: =BV9*$N$16 -> 0 | BW16: =BW9*$N$16 -> 0 | BX16: =BX9*$N$16 -> 0 | BY16: =SUM(P16:BO16) -> 86803334 | BZ16: =BY16-N16 -> 0
G17: 2차중도금 | K17: 0.1 | N17: =K17*$N$23 -> 86803334 | AM17: =N17*AM10 -> 67706600 | AN17: =$N$17*AN9 -> 3472133.4 | AO17: =$N$17*AO9 -> 3472133.4 | AP17: =$N$17*AP9 -> 2604100 | AQ17: =$N$17*AQ9 -> 2604100 | AR17: =$N$17*AR9 -> 868033.34 | AS17: =$N$17*AS9 -> 868033.34 | AT17: =$N$17*AT9 -> 868033.34 | AU17: =$N$17*AU9 -> 868033.34 | ... BP17: =$N$17*BP9 -> 0 | BQ17: =BQ9*$N$17 -> 0 | BR17: =BR9*$N$17 -> 0 | BS17: =BS9*$N$17 -> 0 | BT17: =BT9*$N$17 -> 0 | BU17: =BU9*$N$17 -> 0 | BV17: =BV9*$N$17 -> 0 | BW17: =BW9*$N$17 -> 0 | BX17: =BX9*$N$17 -> 0 | BY17: =SUM(P17:BO17) -> 86803334 | BZ17: =BY17-N17 -> 0
G18: 3차중도금 | K18: 0.1 | N18: =K18*$N$23 -> 86803334 | AS18: =$N$18*AS10 -> 81595134 | AT18: =$N$18*AT9 -> 868033.34 | AU18: =$N$18*AU9 -> 868033.34 | AV18: =$N$18*AV9 -> 868033.34 | AW18: =$N$18*AW9 -> 868033.34 | AX18: =$N$18*AX9 -> 868033.34 | AY18: =$N$18*AY9 -> 0 | AZ18: =$N$18*AZ9 -> 0 | BA18: =$N$18*BA9 -> 0 | ... BP18: =$N$18*BP9 -> 0 | BQ18: =BQ9*$N$18 -> 0 | BR18: =BR9*$N$18 -> 0 | BS18: =BS9*$N$18 -> 0 | BT18: =BT9*$N$18 -> 0 | BU18: =BU9*$N$18 -> 0 | BV18: =BV9*$N$18 -> 0 | BW18: =BW9*$N$18 -> 0 | BX18: =BX9*$N$18 -> 0 | BY18: =SUM(P18:BO18) -> 86803334 | BZ18: =BY18-N18 -> 0
G19: 4차중도금 | K19: 0.1 | N19: =K19*$N$23 -> 86803334 | AY19: =AY10*N19 -> 85935301 | AZ19: =AZ9*$N$19 -> 0 | BA19: =BA9*$N$19 -> 0 | BB19: =BB9*$N$19 -> 0 | BC19: =BC9*$N$19 -> 0 | BD19: =BD9*$N$19 -> 0 | BE19: =BE9*$N$19 -> 0 | BF19: =BF9*$N$19 -> 0 | BG19: =BG9*$N$19 -> 0 | ... BX19: =BX9*$N$19 -> 0 | BY19: =SUM(P19:BO19) -> 86803334 | BZ19: =BY19-N19 -> 0
G20: 5차중도금 | K20: 0.1 | N20: =K20*$N$23 -> 86803334 | BE20: =BE10*$N$20 -> 85935301 | BF20: =BF9*$N$20 -> 0 | BG20: =BG9*$N$20 -> 0 | BH20: =BH9*$N$20 -> 0 | BI20: =BI9*$N$20 -> 868033.34 | BJ20: =BJ9*$N$20 -> 0 | BK20: =BK9*$N$20 -> 0 | BL20: =BL9*$N$20 -> 0 | BM20: =BM9*$N$20 -> 0 | ... BX20: =BX9*$N$20 -> 0 | BY20: =SUM(P20:BO20) -> 86803334 | BZ20: =BY20-N20 -> 0
G21: 6차중도금 | K21: 0.1 | N21: =K21*$N$23 -> 86803334 | BI21: =BI10*$N$21 -> 86803334 | BJ21: =BJ9*$N$21 -> 0 | BK21: =BK9*$N$21 -> 0 | BL21: =BL9*$N$21 -> 0 | BM21: =BM9*$N$21 -> 0 | BN21: =BN9*$N$21 -> 0 | BO21: =BO9*$N$21 -> 0 | BP21: =BP9*$N$21 -> 0 | BQ21: =BQ9*$N$21 -> 0 | ... BX21: =BX9*$N$21 -> 0 | BY21: =SUM(P21:BO21) -> 86803334 | BZ21: =BY21-N21 -> 0
G22: 잔 금 | K22: 0.3 | N22: =K22*$N$23 -> 2.6041e+08 | BL22: =N22*50% -> 1.30205e+08 | BM22: =N22*50% -> 1.30205e+08 | BP22: =BP9*N22 -> 0 | BQ22: =BQ9*$N$22 -> 0 | BU22: =BU10*Y22 -> 0 | BV22: =BV10*AH22 -> 0 | BW22: =BW10*AI22 -> 0 | BX22: =BX10*AJ22 -> 0 | BY22: =SUM(P22:BO22) -> 2.6041e+08 | BZ22: =BY22-N22 -> 0
G23: 소계 | N23: =사업수지표!AL18 -> 8.6803334e+08 | P23: =SUM(P15:P22) -> 0 | R23: =SUM(R15:R22) -> 0 | S23: =SUM(S15:S22) -> 0 | T23: =SUM(T15:T22) -> 0 | U23: =SUM(U15:U22) -> 0 | V23: =SUM(V15:V22) -> 0 | W23: =SUM(W15:W22) -> 0 | X23: =SUM(X15:X22) -> 0 | Y23: =SUM(Y15:Y22) -> 0 | ... BX23: =SUM(BX15:BX22) -> 0 | BY23: =SUM(P23:BO23) -> 8.6803334e+08 | BZ23: =BY23-N23 -> 0
B24: =B11 -> #REF! | G24: 계약금 | K24: 0.1 | N24: =사업수지표!AL19 -> 4399666 | AL24: =$N$24*AL11 -> #REF! | AQ24: =$N$24*AQ11 -> #REF! | AR24: =$N$24*AR11 -> #REF! | AS24: =$N$24*AS11 -> #REF! | AT24: =$N$24*AT11 -> #REF! | AU24: =$N$24*AU11 -> #REF! | AV24: =$N$24*AV11 -> #REF! | AW24: =$N$24*AW11 -> #REF! | AX24: =$N$24*AX11 -> #REF! | ... BP24: =$N$24*BP11 -> #REF! | BY24: 0.0268 | BZ24: =BY24-N24 -> -4399666
G25: 1차중도금 | K25: 0.1 | N25: =사업수지표!AL20 -> 3176318.5 | AS25: =$N$25*AS12 -> #REF! | AT25: =$N$25*AT11 -> #REF! | AU25: =$N$25*AU11 -> #REF! | AV25: =$N$25*AV11 -> #REF! | AW25: =$N$25*AW11 -> #REF! | AX25: =$N$25*AX11 -> #REF! | AY25: =$N$25*AY11 -> #REF! | AZ25: =$N$25*AZ11 -> #REF! | BA25: =$N$25*BA11 -> #REF! | ... BP25: =$N$25*BP11 -> #REF! | BY25: 0.0268 | BZ25: =BY25-N25 -> -3176318.5
G26: 2차중도금 | K26: 0.1 | N26: =사업수지표!AL21 -> 7575984.5 | AV26: =$N$26*AV12 -> #REF! | AW26: =$N$26*AW11 -> #REF! | AX26: =$N$26*AX11 -> #REF! | AY26: =$N$26*AY11 -> #REF! | AZ26: =$N$26*AZ11 -> #REF! | BA26: =$N$26*BA11 -> #REF! | BB26: =$N$26*BB11 -> #REF! | BC26: =$N$26*BC11 -> #REF! | BD26: =$N$26*BD11 -> #REF! | ... BP26: =$N$26*BP11 -> #REF! | BY26: 0.0268 | BZ26: =BY26-N26 -> -7575984.5
G27: 3차중도금 | K27: 0.1 | N27: =사업수지표!AL22 -> 41470000 | AY27: =$N$27*AY12 -> #REF! | AZ27: =$N$27*AZ11 -> #REF! | BA27: =$N$27*BA11 -> #REF! | BB27: =$N$27*BB11 -> #REF! | BC27: =$N$27*BC11 -> #REF! | BD27: =$N$27*BD11 -> #REF! | BE27: =$N$27*BE11 -> #REF! | BF27: =$N$27*BF11 -> #REF! | BG27: =$N$27*BG11 -> #REF! | ... BP27: =$N$27*BP11 -> #REF! | BY27: 0.0268 | BZ27: =BY27-N27 -> -41470000
G28: 4차중도금 | K28: 0.1 | N28: =사업수지표!AL23 -> 9.1707932e+08 | BB28: =$N$28*BB12 -> #REF! | BC28: =$N$28*BC11 -> #REF! | BD28: =$N$28*BD11 -> #REF! | BE28: =$N$28*BE11 -> #REF! | BF28: =$N$28*BF11 -> #REF! | BG28: =$N$28*BG11 -> #REF! | BH28: =$N$28*BH11 -> #REF! | BI28: =$N$28*BI11 -> #REF! | BJ28: =$N$28*BJ11 -> #REF! | ... BP28: =$N$28*BP11 -> #REF! | BY28: 0.0268 | BZ28: =BY28-N28 -> -9.1707932e+08
G29: 5차중도금 | K29: 0.1 | N29: =사업수지표!AL24 -> 96000000 | BE29: =$N$29*BE12 -> #REF! | BF29: =$N$29*BF11 -> #REF! | BG29: =$N$29*BG11 -> #REF! | BH29: =$N$29*BH11 -> #REF! | BI29: =$N$29*BI11 -> #REF! | BJ29: =$N$29*BJ11 -> #REF! | BK29: =$N$29*BK11 -> #REF! | BL29: =$N$29*BL11 -> #REF! | BM29: =$N$29*BM11 -> #REF! | ... BP29: =$N$29*BP11 -> #REF! | BY29: 0.0268 | BZ29: =BY29-N29 -> -96000000
G30: 6차중도금 | K30: 0.1 | N30: =사업수지표!AL25 -> 13969158 | BH30: =$N$30*BH12 -> #REF! | BI30: =$N$30*BI11 -> #REF! | BJ30: =$N$30*BJ11 -> #REF! | BK30: =$N$30*BK11 -> #REF! | BL30: =$N$30*BL11 -> #REF! | BM30: =$N$30*BM11 -> #REF! | BN30: =$N$30*BN11 -> #REF! | BO30: =$N$30*BO11 -> #REF! | BP30: =$N$30*BP11 -> #REF! | BY30: 0.0268 | BZ30: =BY30-N30 -> -13969158
G31: 잔 금 | K31: 0.3 | N31: =사업수지표!AL28 -> 1603249 | BK31: =$N$31*BK12*5% -> #REF! | BL31: =$N$31*BL12*40% -> #REF! | BM31: =$N$31*BM12*55% -> #REF! | BN31: =$N$31*BN12*55% -> #REF! | BY31: 0.0268 | BZ31: =BY31-N31 -> -1603249
G32: 소계 | N32: =사업수지표!AL29 -> 3882030.6 | X32: =SUM(X24:X31) -> 0 | Y32: =SUM(Y24:Y31) -> 0 | AH32: =SUM(AH24:AH31) -> 0 | AI32: =SUM(AI24:AI31) -> 0 | AJ32: =SUM(AJ24:AJ31) -> 0 | AK32: =SUM(AK24:AK31) -> 0 | AL32: =SUM(AL24:AL31) -> #REF! | AQ32: =SUM(AQ24:AQ31) -> #REF! | AR32: =SUM(AR24:AR31) -> #REF! | AS32: =SUM(AS24:AS31) -> #REF! | AT32: =SUM(AT24:AT31) -> #REF! | AU32: =SUM(AU24:AU31) -> #REF! | AV32: =SUM(AV24:AV31) -> #REF! | AW32: =SUM(AW24:AW31) -> #REF! | AX32: =SUM(AX24:AX31) -> #REF! | ... BP32: =SUM(BP24:BP31) -> #REF! | BY32: 0.0268 | BZ32: =BY32-N32 -> -3882030.6
B33: =B13 -> 상가 | G33: 계약금 | K33: 0.1 | N33: =K33*$N$39 -> 757598.45 | AQ33: =N33*AQ13 -> 151519.69 | AR33: =N33*AR13 -> 37879.923 | AS33: =N33*AS13 -> 37879.923 | AT33: =N33*AT13 -> 37879.923 | AU33: =N33*AU13 -> 37879.923 | AV33: =$N$33*AV13 -> 37879.923 | AW33: =$N$33*AW13 -> 37879.923 | AX33: =$N$33*AX13 -> 37879.923 | AY33: =$N$33*AY13 -> 75759.845 | AZ33: =$N$33*AZ13 -> 37879.923 | BA33: =$N$33*BA13 -> 37879.923 | BB33: =$N$33*BB13 -> 37879.923 | BC33: =$N$33*BC13 -> 37879.923 | ... BK33: =$N$33*BK13 -> 0 | BS33: =BS13*$N$33 -> 0 | BT33: =BT13*$N$33 -> 0 | BU33: =BU13*$N$33 -> 0 | BV33: =BV13*$N$33 -> 0 | BW33: =BW13*$N$33 -> 0 | BX33: =BX13*$N$33 -> 0 | BY33: =SUM(P33:BO33) -> 757598.45 | BZ33: =BY33-N33 -> 0
G34: 1차중도금 | K34: 0.1 | N34: =K34*$N$39 -> 757598.45 | AV34: =N34*AV14 -> 340919.3 | AW34: =N34*AW13 -> 37879.923 | AX34: =N34*AX13 -> 37879.923 | AY34: =N34*AY13 -> 75759.845 | AZ34: =N34*AZ13 -> 37879.923 | BA34: =N34*BA13 -> 37879.923 | BB34: =N34*BB13 -> 37879.923 | BC34: =N34*BC13 -> 37879.923 | BD34: =N34*BD13 -> 37879.923 | BE34: =N34*BE13 -> 0 | BF34: =N34*BF13 -> 37879.923 | BG34: =N34*BG13 -> 0 | BH34: =N34*BH13 -> 37879.923 | BI34: =X34*BI13 -> 0 | BJ34: =Y34*BJ13 -> 0 | BY34: =SUM(P34:BO34) -> 757598.45 | BZ34: =BY34-N34 -> 0
G35: 2차중도금 | K35: 0.1 | N35: =K35*$N$39 -> 757598.45 | BA35: =N35*BA14 -> 568198.84 | BB35: =N35*BB13 -> 37879.923 | BC35: =N35*BC13 -> 37879.923 | BD35: =N35*BD13 -> 37879.923 | BF35: =N35*BF13 -> 37879.923 | BH35: =N35*BH13 -> 37879.923 | BY35: =SUM(P35:BO35) -> 757598.45 | BZ35: =BY35-N35 -> 0
G36: 3차중도금 | K36: 0.1 | N36: =K36*$N$39 -> 757598.45 | BE36: =N36*BE14 -> 681838.61 | BF36: =N36*BF13 -> 37879.923 | BH36: =N36*BH13 -> 37879.923 | BY36: =SUM(P36:BO36) -> 757598.45 | BZ36: =BY36-N36 -> 0
G37: 4차중도금 | K37: 0.1 | N37: =K37*$N$39 -> 757598.45 | BI37: =N37*BI14 -> 757598.45 | BY37: =SUM(P37:BO37) -> 757598.45 | BZ37: =BY37-N37 -> 0
G38: 잔 금 | K38: 0.5 | N38: =K38*$N$39 -> 3787992.2 | BL38: =N38*50% -> 1893996.1 | BM38: =N38*50% -> 1893996.1 | BY38: =SUM(P38:BO38) -> 3787992.2 | BZ38: =BY38-N38 -> 0
G39: 소계 | N39: =사업수지표!AL21 -> 7575984.5 | AP39: =SUM(AP33:AP38) -> 0 | AQ39: =SUM(AQ33:AQ38) -> 151519.69 | AR39: =SUM(AR33:AR38) -> 37879.923 | AS39: =SUM(AS33:AS38) -> 37879.923 | AT39: =SUM(AT33:AT38) -> 37879.923 | AU39: =SUM(AU33:AU38) -> 37879.923 | AV39: =SUM(AV33:AV38) -> 378799.22 | AW39: =SUM(AW33:AW38) -> 75759.845 | ... BX39: =SUM(BX33:BX38) -> 0 | BY39: =SUM(P39:BO39) -> 7575984.5 | BZ39: =BY39-N39 -> 0
B40: =[28]사업수지표!B25 -> 발코니 확장 | G40: 계약금 | K40: 0.1 | N40: =N42*K40 -> 4147000 | AA40: =AA9*$N$40 -> 829400 | AB40: =AB9*$N$40 -> 414700 | AC40: =AC9*$N$40 -> 207350 | AD40: =AD9*$N$40 -> 207350 | AE40: =AE9*$N$40 -> 414700 | AF40: =AF9*$N$40 -> 124410 | AG40: =AG9*$N$40 -> 82940 | AH40: =AH9*$N$40 -> 165880 | ... BP40: =BP9*$N$40 -> 0 | BQ40: =BQ9*N40 -> 0 | BR40: =$N$40*BR9*10% -> 0 | BS40: =$N$40*BS9*10% -> 0 | BT40: =$N$40*BT9*10% -> 0 | BU40: =$N$40*BU9*10% -> 0 | BV40: =$N$40*BV9*10% -> 0 | BW40: =$N$40*BW9*10% -> 0 | BX40: =$N$40*BX9*10% -> 0 | BY40: =SUM(P40:BO40) -> 4147000 | BZ40: =BY40-N40 -> 0
...

Sheet Exit 분양률
B1: 경기도 화성시 장짐리 공동주택 신축사업 Exit 분양률
B4: [총 분양수입금] | F4: (단위 : 천원) | H4: [잔금 비율]
B5: 구 분 | C5: 공동주택 | D5: 발코니확장비 | E5: 근린생활시설 | F5: 매출 합계 | H5: 공동주택 | I5: 발코니확장비 | J5: 근린생활시설
B6: 금액 | C6: =사업수지표!Z18 -> 8.6803334e+08 | D6: =사업수지표!Z22 -> 37700000 | E6: =사업수지표!Z21 -> 6929246.5 | F6: =C6+D6+E6 -> 9.1266259e+08 | H6: 0.3 | I6: 1 | J6: 0.5
B7: 누계액 | C7: =C6 -> 8.6803334e+08 | D7: =C7+D6 -> 9.0573334e+08 | E7: =D7+E6 -> 9.1266259e+08 | F7: =E7=F6 -> TRUE
B10: [분양수입금 잔금] | F10: (단위 : 천원)
B11: 구 분 | C11: 공동주택 | D11: 발코니확장비 | E11: 근린생활시설 | F11: 잔금 합계
B12: 금액 | C12: =C6*H6 -> 2.6041e+08 | D12: =D6*I6 -> 37700000 | E12: =E6*J6 -> 3464623.2 | F12: =C12+D12+E12 -> 3.0157463e+08
B13: 누계액 | C13: =C12 -> 2.6041e+08 | D13: =C13+D12 -> 2.9811e+08 | E13: =E12+D13 -> 3.0157463e+08 | F13: =E13=F12 -> TRUE
E15: =C13+E12 -> 2.6387463e+08
B16: [공동주택, 발코니확장비, 근린생활시설 분양수입금(잔금) 기준] | F16: (단위 : 천원)
B17: 잔금납입률 | C17: 대출금상환 | D17: 대출금잔액 | E17: LTV | F17: 비 고
B18: 0 | D18: =사업수지표!AW81 -> 149000000 | E18: =IF(($D$18-C18)/($E$13*(1-B18))>0,($D$18-C18)/($E$13*(1-B18)),0) -> 0.4940734
B19: 0.1 | C19: =$E$13*B19 -> 30157463 | D19: =IF($D$18-C19>0,$D$18-C19,0) -> 1.1884254e+08 | E19: =IF(($D$18-C19)/($E$13*(1-B19))>0,($D$18-C19)/($E$13*(1-B19)),0) -> 0.43785933
B20: 0.2 | C20: =$E$13*B20 -> 60314925 | D20: =IF($D$18-C20>0,$D$18-C20,0) -> 88685075 | E20: =IF(($D$18-C20)/($E$13*(1-B20))>0,($D$18-C20)/($E$13*(1-B20)),0) -> 0.36759175
B21: 0.3 | C21: =$E$13*B21 -> 90472388 | D21: =IF($D$18-C21>0,$D$18-C21,0) -> 58527612 | E21: =IF(($D$18-C21)/($E$13*(1-B21))>0,($D$18-C21)/($E$13*(1-B21)),0) -> 0.27724771
B22: 0.4 | C22: =$E$13*B22 -> 1.2062985e+08 | D22: =IF($D$18-C22>0,$D$18-C22,0) -> 28370150 | E22: =IF(($D$18-C22)/($E$13*(1-B22))>0,($D$18-C22)/($E$13*(1-B22)),0) -> 0.156789
B23: 0.4940734 | C23: =$E$13*B23 -> 1.49e+08 | D23: =IF($D$18-C23<0,0,$D$18-C23) -> 5.9604645e-08 | E23: =IF(($D$18-C23)/($E$13*(1-B23))>0,($D$18-C23)/($E$13*(1-B23)),0) -> 3.9065896e-16
B24: 0.5 | C24: =$E$13*B24 -> 1.5078731e+08 | E24: =IF(($D$18-C24)/($E$13*(1-B24))>0,($D$18-C24)/($E$13*(1-B24)),0) -> 0
B27: [공동주택, 근생 분양수입금(잔금) 기준] | F27: (단위 : 천원)
B28: 잔금납입률 | C28: 대출금상환 | D28: 대출금잔액 | E28: LTV | F28: 비 고
B29: 0 | C29: =D13*B29 -> 0 | D29: =D18 -> 149000000 | E29: =IF(($D$29-C29)/(E15*(1-B29))>0,($D$29-C29)/(E15*(1-B29)),0) -> 0.5646621
B30: 0.1 | C30: =E15*B30 -> 26387463 | D30: =IF($D$29-C30>0,$D$29-C30,0) -> 1.2261254e+08 | E30: =IF(($D$29-C30)/(E15*(1-B30))>0,($D$29-C30)/(E15*(1-B30)),0) -> 0.51629122
B31: 0.2 | C31: =E15*B31 -> 52774925 | D31: =IF($D$29-C31>0,$D$29-C31,0) -> 96225075 | E31: =IF(($D$29-C31)/(E15*(1-B31))>0,($D$29-C31)/(E15*(1-B31)),0) -> 0.45582763
B32: 0.3 | C32: =E15*B32 -> 79162388 | D32: =IF($D$29-C32>0,$D$29-C32,0) -> 69837612 | E32: =IF(($D$29-C32)/(E15*(1-B32))>0,($D$29-C32)/(E15*(1-B32)),0) -> 0.37808871
B33: 0.4 | C33: =E15*B33 -> 1.0554985e+08 | D33: =IF($D$29-C33>0,$D$29-C33,0) -> 43450150 | E33: =IF(($D$29-C33)/(E15*(1-B33))>0,($D$29-C33)/(E15*(1-B33)),0) -> 0.27443683
B34: 0.5 | C34: =E15*B34 -> 1.3193731e+08 | D34: =IF($D$29-C34>0,$D$29-C34,0) -> 17062687 | E34: =IF(($D$29-C34)/(E15*(1-B34))>0,($D$29-C34)/(E15*(1-B34)),0) -> 0.1293242
B35: 0.5646621 | C35: =E15*B35 -> 1.49e+08 | D35: =IF($D$29-C35>0,$D$29-C35,0) -> 5.9604645e-08 | E35: =IF(($D$29-C35)/(E15*(1-B35))>0,($D$29-C35)/(E15*(1-B35)),0) -> 5.1886694e-16
B37: [공동주택, 발코니확장비(잔금) 기준] | F37: (단위 : 천원)
B38: 잔금납입률 | C38: 대출금상환 | D38: 대출금잔액 | E38: LTV | F38: 비 고
B39: 0 | D39: 149000000 | E39: =IF(($D$18-C39)/(D13*(1-B39))>0,($D$18-C39)/(D13*(1-B39)),0) -> 0.4998155
B40: 0.1 | C40: =D13*B40 -> 29811000 | D40: =IF($D$18-C40>0,$D$18-C40,0) -> 1.19189e+08 | E40: =IF(($D$18-C40)/(D13*(1-B40))>0,($D$18-C40)/(D13*(1-B40)),0) -> 0.44423945
B41: 0.2 | C41: =D13*B41 -> 59622000 | D41: =IF($D$18-C41>0,$D$18-C41,0) -> 89378000 | E41: =IF(($D$18-C41)/(D13*(1-B41))>0,($D$18-C41)/(D13*(1-B41)),0) -> 0.37476938
B42: 0.3 | C42: =D13*B42 -> 89433001 | D42: =IF($D$18-C42>0,$D$18-C42,0) -> 59566999 | E42: =IF(($D$18-C42)/(D13*(1-B42))>0,($D$18-C42)/(D13*(1-B42)),0) -> 0.28545072
B43: 0.4 | C43: =D13*B43 -> 1.19244e+08 | D43: =IF($D$18-C43>0,$D$18-C43,0) -> 29755999 | E43: =IF(($D$18-C43)/(D13*(1-B43))>0,($D$18-C43)/(D13*(1-B43)),0) -> 0.16635917
B44: 0.4998155 | C44: =D13*B44 -> 149000000 | D44: =IF($D$18-C44<0,0,$D$18-C44) -> 0 | E44: =IF(($D$18-C44)/($E$13*(1-B44))>0,($D$18-C44)/($E$13*(1-B44)),0) -> 0

Sheet 자금판-HF
B1: PF 자금판
F2: 대출기간 | H2: 41
B3: IN | E3: OUT
B4: PF | C4: Tr.A | D4: 22000000000 | E4: 브릿지상환 (170억원) | F4: 중랑신협 | H4: 10000000000
C5: Tr.B | D5: 1500000000 | F5: 바로저축 | H5: 4000000000 | K5: 상환 | L5: 대출잔액 | M5: 비고
B6: 추가에쿼티 | F6: LK | J6: 기표 | L6: =SUM(D4:D5) -> 23500000000
F7: 웨이브 | H7: 3000000000 | J7: +4M | L7: =L6-K7 -> 23500000000
E8: PF비용예치 | F8: 금융예비비 | H8: 30000000
F9: HF수수료(0.5%) | H9: =현금흐름표!#REF!*1000 -> #REF!
F10: 금융주관(1%) | H10: =SUM(D4:D5)*1% -> 235000000
F11: PF 취급수수료 | G11: Tr.A (2.0%) | H11: =D4*2% -> 440000000
G12: Tr.B (17.9%) | H12: =D5*17.9% -> 268500000
E13: PF이자 | F13: 현금흐름표상 PF이자
F14: 41 | G14: Tr.A (6.5%) | H14: =D4*6.5%/12*F14 -> 4.8858333e+09
G15: Tr.B (8.0%) | H15: =D5*8%/12*F14 -> 410000000
F16: 이자합계 | H16: =SUM(H14:H15) -> 5.2958333e+09
B17: 계 | D17: =SUM(D4:D16) -> 23500000000 | E17: 계 | H17: =SUM(H4:H12)+H13+H16 -> #REF!

Sheet 할인분양 계산
B2: ■ 할인분양 적용
B4: 공동주택 수입 | C4: =SUM(사업수지표!#REF!,사업수지표!#REF!) -> #REF!
B5: 상가 수입 | C5: =사업수지표!#REF! -> #REF!
B6: 필요사업비 | C6: =사업수지표!AT89 -> 4.8990429e+08
B7: 84A | C7: =사업수지표!#REF! -> #REF! | D7: =C7*0.8 -> #REF!
B8: 84B | C8: =사업수지표!#REF! -> #REF! | D8: =C8*0.8 -> #REF!
B9: 107 | C9: =사업수지표!#REF! -> #REF! | D9: =C9*0.8 -> #REF!
B11: 분양대금 | D11: 부족사업비 | E11: 미분양액 | F11: 미분양할인율 | G11: 84A | H11: 84B | I11: 107
B12: 0.5 | C12: =$C$4*B12 -> #REF! | D12: =$C$6-C12 -> #REF! | E12: =SUM($C$4:$C$5)-C12 -> #REF! | F12: =1-D12/E12 -> #REF! | G12: =$C$7*(1-F12) -> #REF! | H12: =$C$8*(1-F12) -> #REF! | I12: =$C$9*(1-F12) -> #REF!
B13: 0.4 | C13: =$C$4*B13 -> #REF! | D13: =$C$6-C13 -> #REF! | E13: =SUM($C$4:$C$5)-C13 -> #REF! | F13: =1-D13/E13 -> #REF! | G13: =$C$7*(1-F13) -> #REF! | H13: =$C$8*(1-F13) -> #REF! | I13: =$C$9*(1-F13) -> #REF!
B14: 0.3 | C14: =$C$4*B14 -> #REF! | D14: =$C$6-C14 -> #REF! | E14: =SUM($C$4:$C$5)-C14 -> #REF! | F14: =1-D14/E14 -> #REF! | G14: =$C$7*(1-F14) -> #REF! | H14: =$C$8*(1-F14) -> #REF! | I14: =$C$9*(1-F14) -> #REF!
B15: 0.2 | C15: =$C$4*B15 -> #REF! | D15: =$C$6-C15 -> #REF! | E15: =SUM($C$4:$C$5)-C15 -> #REF! | F15: =1-D15/E15 -> #REF! | G15: =$C$7*(1-F15) -> #REF! | H15: =$C$8*(1-F15) -> #REF! | I15: =$C$9*(1-F15) -> #REF!
B16: 0.1 | C16: =$C$4*B16 -> #REF! | D16: =$C$6-C16 -> #REF! | E16: =SUM($C$4:$C$5)-C16 -> #REF! | F16: =1-D16/E16 -> #REF! | G16: =$C$7*(1-F16) -> #REF! | H16: =$C$8*(1-F16) -> #REF! | I16: =$C$9*(1-F16) -> #REF!
B17: 0.09 | C17: =$C$4*B17 -> #REF! | D17: =$C$6-C17 -> #REF! | E17: =SUM($C$4:$C$5)-C17 -> #REF! | F17: =1-D17/E17 -> #REF! | G17: =$C$7*(1-F17) -> #REF! | H17: =$C$8*(1-F17) -> #REF! | I17: =$C$9*(1-F17) -> #REF!
B18: 0.05 | C18: =$C$4*B18 -> #REF! | D18: =$C$6-C18 -> #REF! | E18: =SUM($C$4:$C$5)-C18 -> #REF! | F18: =1-D18/E18 -> #REF! | G18: =$C$7*(1-F18) -> #REF! | H18: =$C$8*(1-F18) -> #REF! | I18: =$C$9*(1-F18) -> #REF!
C20: 238065 | D20: 0.378 | E20: =C20/(1-D20) -> 382741.16 | F20: =E20*0.8 -> 306192.93
C21: 265300 | D21: 0.307 | E21: =C21/(1-D21) -> 382828.28
C22: 267560 | D22: 0.301 | E22: =C22/(1-D22) -> 382775.39

Sheet IRR 계산
A1: PF대출기간 | C1: IRR | G1: *단위 : 억원
A2: 50 | B2: 개월 | C2: 0.11 | H2: 준공시점 상환
C3: 개월 | D3: 12 | E3: 12 | F3: 12 | G3: 12 | H3: 2
C4: 연 | D4: 1 | E4: 2 | F4: 3 | G4: 4 | H4: 4.1666667
B6: 대출금액(원금) | C6: 149000000
B7: 이자 | D7: =$C$6*$C$2 -> 16390000 | E7: =$C$6*$C$2 -> 16390000 | F7: =$C$6*$C$2 -> 16390000 | G7: =$C$6*$C$2 -> 16390000 | H7: =C6*C2*(2/12) -> 2731666.7
H8: =G7*(1+$C$2)^(D4+($H$3/12)) -> 18512103
H9: =F7*(1+$C$2)^(E4+($H$3/12)) -> 20548435
H10: =E7*(1+$C$2)^(F4+($H$3/12)) -> 22808762
H11: =D7*(1+$C$2)^(G4+($H$3/12)) -> 25317726
G12: 총 이자금액(천원) | H12: =SUM(H7:H11) -> 89918693

Sheet 공정률
B1: ▣ 공정률
C2: 구분 | F2: =현금흐름표!AA6 -> 46419 | G2: =현금흐름표!AB6 -> 46447 | H2: =현금흐름표!AC6 -> 46478 | I2: =현금흐름표!AD6 -> 46508 | J2: =현금흐름표!AE6 -> 46539 | K2: =현금흐름표!AF6 -> 46569 | L2: =현금흐름표!AG6 -> 46600 | M2: =현금흐름표!AH6 -> 46631 | ... BA2: =현금흐름표!BV6 -> 47423
C3: 공사진행스케줄 | F3: 1 | G3: =F3+1 -> 2 | H3: =G3+1 -> 3 | I3: =H3+1 -> 4 | J3: =I3+1 -> 5 | K3: =J3+1 -> 6 | L3: =K3+1 -> 7 | M3: =L3+1 -> 8 | N3: =M3+1 -> 9 | ... BA3: =AZ3+1 -> 48
C4: 주상복합 | D4: 공정률 | E4: =SUM(F4:BA4) -> 1 | F4: =VLOOKUP($E$5,$C8:$AZ41,F3+2) -> 0.0096 | G4: =VLOOKUP($E$5,$C8:$AZ41,G3+2) -> 0.0096 | H4: =VLOOKUP($E$5,$C8:$AZ41,H3+2) -> 0.0116 | I4: =VLOOKUP($E$5,$C8:$AZ41,I3+2) -> 0.0116 | J4: =VLOOKUP($E$5,$C8:$AZ41,J3+2) -> 0.0136 | K4: =VLOOKUP($E$5,$C8:$AZ41,K3+2) -> 0.0136 | L4: =VLOOKUP($E$5,$C8:$AZ41,L3+2) -> 0.0186 | M4: =VLOOKUP($E$5,$C8:$AZ41,M3+2) -> 0.0186 | ... BA4: =VLOOKUP($E$5,$C8:$AZ41,BA3+2) -> 0
D5: 누계공정률 | E5: 37 | F5: =F4 -> 0.0096 | G5: =F5+G4 -> 0.0192 | H5: =G5+H4 -> 0.0308 | I5: =H5+I4 -> 0.0424 | J5: =I5+J4 -> 0.056 | K5: =J5+K4 -> 0.0696 | L5: =K5+L4 -> 0.0882 | M5: =L5+M4 -> 0.1068 | N5: =M5+N4 -> 0.1284 | ... BA5: =AZ5+BA4 -> 1
C7: ※ 공정률 Table
C8: 15 | D8: 개월 | E8: 0.049 | F8: 0.049 | G8: 0.053 | H8: 0.053 | I8: 0.057 | J8: 0.057 | K8: 0.066 | L8: 0.066 | M8: 0.073 | N8: 0.073 | O8: 0.078 | P8: 0.078 | Q8: 0.083 | R8: 0.083 | S8: 0.082 | BA8: 1
C9: 16 | D9: 개월 | E9: 0.043 | F9: 0.043 | G9: 0.047 | H9: 0.047 | I9: 0.051 | J9: 0.051 | K9: 0.06 | L9: 0.06 | M9: 0.067 | N9: 0.067 | O9: 0.072 | P9: 0.072 | Q9: 0.077 | R9: 0.077 | S9: 0.085 | T9: 0.081 | BA9: 1
C10: 17 | D10: 개월 | E10: 0.038 | F10: 0.038 | G10: 0.042 | H10: 0.042 | I10: 0.046 | J10: 0.046 | K10: 0.055 | L10: 0.055 | M10: 0.062 | N10: 0.062 | O10: 0.067 | P10: 0.067 | Q10: 0.072 | R10: 0.072 | S10: 0.08 | T10: 0.08 | U10: 0.076 | BA10: 1
C11: 18 | D11: 개월 | E11: 0.0335 | F11: 0.0335 | G11: 0.0375 | H11: 0.0375 | I11: 0.0415 | J11: 0.0415 | K11: 0.0505 | L11: 0.0505 | M11: 0.0575 | N11: 0.0575 | O11: 0.0625 | P11: 0.0625 | Q11: 0.0675 | R11: 0.0675 | S11: 0.0755 | T11: 0.0755 | U11: 0.0755 | V11: 0.0725 | BA11: 1
C12: 19 | D12: 개월 | E12: 0.0295 | F12: 0.0295 | G12: 0.0335 | H12: 0.0335 | I12: 0.0375 | J12: 0.0375 | K12: 0.0465 | L12: 0.0465 | M12: 0.0535 | N12: 0.0535 | O12: 0.0585 | P12: 0.0585 | Q12: 0.0635 | R12: 0.0635 | S12: 0.0715 | T12: 0.0715 | U12: 0.0715 | V12: 0.0715 | W12: 0.069 | BA12: 1
C13: 20 | D13: 개월 | E13: 0.0263 | F13: 0.0263 | G13: 0.0303 | H13: 0.0303 | I13: 0.0343 | J13: 0.0343 | K13: 0.0433 | L13: 0.0433 | M13: 0.0503 | N13: 0.0503 | O13: 0.0553 | P13: 0.0553 | Q13: 0.0603 | R13: 0.0603 | S13: 0.0683 | T13: 0.0683 | U13: 0.0683 | V13: 0.0683 | W13: 0.0683 | X13: 0.0583 | BA13: 1
C14: 21 | D14: 개월 | E14: 0.0228 | F14: 0.0228 | G14: 0.0268 | H14: 0.0268 | I14: 0.0308 | J14: 0.0308 | K14: 0.0398 | L14: 0.0398 | M14: 0.0468 | N14: 0.0468 | O14: 0.0518 | P14: 0.0518 | Q14: 0.0568 | R14: 0.0568 | S14: 0.0648 | T14: 0.0648 | U14: 0.0648 | V14: 0.0648 | W14: 0.0648 | X14: 0.0648 | Y14: 0.06 | BA14: 1
C15: 22 | D15: 개월 | E15: 0.0203 | F15: 0.0203 | G15: 0.0243 | H15: 0.0243 | I15: 0.0283 | J15: 0.0283 | K15: 0.0373 | L15: 0.0373 | M15: 0.0443 | N15: 0.0443 | O15: 0.0493 | P15: 0.0493 | Q15: 0.0543 | R15: 0.0543 | S15: 0.0623 | T15: 0.0623 | U15: 0.0623 | V15: 0.0623 | W15: 0.0623 | X15: 0.0623 | Y15: 0.0573 | Z15: 0.0527 | BA15: 1
C16: 23 | D16: 개월 | E16: 0.0178 | F16: 0.0178 | G16: 0.0218 | H16: 0.0218 | I16: 0.0258 | J16: 0.0258 | K16: 0.0348 | L16: 0.0348 | M16: 0.0418 | N16: 0.0418 | O16: 0.0468 | P16: 0.0468 | Q16: 0.0518 | R16: 0.0518 | S16: 0.0598 | T16: 0.0598 | U16: 0.0598 | V16: 0.0598 | W16: 0.0598 | X16: 0.0598 | Y16: 0.0548 | Z16: 0.0548 | AA16: 0.0504 | BA16: 1
C17: 24 | D17: 개월 | E17: 0.0158 | F17: 0.0158 | G17: 0.0198 | H17: 0.0198 | I17: 0.0238 | J17: 0.0238 | K17: 0.0328 | L17: 0.0328 | M17: 0.0398 | N17: 0.0398 | O17: 0.0448 | P17: 0.0448 | Q17: 0.0498 | R17: 0.0498 | S17: 0.0578 | T17: 0.0578 | U17: 0.0578 | V17: 0.0578 | W17: 0.0578 | X17: 0.0578 | Y17: 0.0528 | Z17: 0.0528 | AA17: 0.0478 | AB17: 0.0466 | BA17: 1
C18: 25 | D18: 개월 | E18: 0.014 | F18: 0.014 | G18: 0.018 | H18: 0.018 | I18: 0.022 | J18: 0.022 | K18: 0.031 | L18: 0.031 | M18: 0.038 | N18: 0.038 | O18: 0.043 | P18: 0.043 | Q18: 0.048 | R18: 0.048 | S18: 0.056 | T18: 0.056 | U18: 0.056 | V18: 0.056 | W18: 0.056 | X18: 0.056 | Y18: 0.051 | Z18: 0.051 | AA18: 0.046 | AB18: 0.046 | AC18: 0.042 | BA18: 1
C19: 26 | D19: 개월 | E19: 0.0125 | F19: 0.0125 | G19: 0.0165 | H19: 0.0165 | I19: 0.0205 | J19: 0.0205 | K19: 0.0295 | L19: 0.0295 | M19: 0.0365 | N19: 0.0365 | O19: 0.0415 | P19: 0.0415 | Q19: 0.0465 | R19: 0.0465 | S19: 0.0545 | T19: 0.0545 | U19: 0.0545 | V19: 0.0545 | W19: 0.0545 | X19: 0.0545 | Y19: 0.0495 | Z19: 0.0495 | AA19: 0.0445 | AB19: 0.0445 | AC19: 0.0395 | AD19: 0.0385 | BA19: 1
C20: 27 | D20: 개월 | E20: 0.011 | F20: 0.011 | G20: 0.015 | H20: 0.015 | I20: 0.019 | J20: 0.019 | K20: 0.028 | L20: 0.028 | M20: 0.035 | N20: 0.035 | O20: 0.04 | P20: 0.04 | Q20: 0.045 | R20: 0.045 | S20: 0.053 | T20: 0.053 | U20: 0.053 | V20: 0.053 | W20: 0.053 | X20: 0.053 | Y20: 0.048 | Z20: 0.048 | AA20: 0.043 | AB20: 0.043 | AC20: 0.038 | AD20: 0.038 | AE20: 0.038 | BA20: 1
C21: 28 | D21: 개월 | E21: 0.0099 | F21: 0.0099 | G21: 0.0139 | H21: 0.0139 | I21: 0.0179 | J21: 0.0179 | K21: 0.0269 | L21: 0.0269 | M21: 0.0339 | N21: 0.0339 | O21: 0.0389 | P21: 0.0389 | Q21: 0.0439 | R21: 0.0439 | S21: 0.0519 | T21: 0.0519 | U21: 0.0519 | V21: 0.0519 | W21: 0.0519 | X21: 0.0519 | Y21: 0.0469 | Z21: 0.0469 | AA21: 0.0419 | AB21: 0.0419 | AC21: 0.0369 | AD21: 0.0369 | AE21: 0.0339 | AF21: 0.0327 | BA21: 1
C22: 29 | D22: 개월 | E22: 0.0088 | F22: 0.0088 | G22: 0.0128 | H22: 0.0128 | I22: 0.0168 | J22: 0.0168 | K22: 0.0258 | L22: 0.0258 | M22: 0.0328 | N22: 0.0328 | O22: 0.0378 | P22: 0.0378 | Q22: 0.0428 | R22: 0.0428 | S22: 0.0508 | T22: 0.0508 | U22: 0.0508 | V22: 0.0508 | W22: 0.0508 | X22: 0.0508 | Y22: 0.0458 | Z22: 0.0458 | AA22: 0.0408 | AB22: 0.0408 | AC22: 0.0358 | AD22: 0.0358 | AE22: 0.0328 | AF22: 0.0328 | AG22: 0.0296 | BA22: 1
C23: 30 | D23: 개월 | E23: 0.008 | F23: 0.008 | G23: 0.012 | H23: 0.012 | I23: 0.016 | J23: 0.016 | K23: 0.025 | L23: 0.025 | M23: 0.032 | N23: 0.032 | O23: 0.037 | P23: 0.037 | Q23: 0.042 | R23: 0.042 | S23: 0.05 | T23: 0.05 | U23: 0.05 | V23: 0.05 | W23: 0.05 | X23: 0.05 | Y23: 0.045 | Z23: 0.045 | AA23: 0.04 | AB23: 0.04 | AC23: 0.035 | AD23: 0.035 | AE23: 0.032 | AF23: 0.032 | AG23: 0.03 | AH23: 0.022 | BA23: 1
C24: 31 | D24: 개월 | E24: 0.0164 | F24: 0.0164 | G24: 0.0184 | H24: 0.0184 | I24: 0.0204 | J24: 0.0204 | K24: 0.0254 | L24: 0.0254 | M24: 0.0284 | N24: 0.0284 | O24: 0.0314 | P24: 0.0314 | Q24: 0.0334 | R24: 0.0334 | S24: 0.0354 | T24: 0.0354 | U24: 0.0354 | V24: 0.0354 | W24: 0.0354 | X24: 0.0354 | Y24: 0.0374 | Z24: 0.0374 | AA24: 0.0374 | AB24: 0.0374 | AC24: 0.0394 | AD24: 0.0394 | AE24: 0.0414 | AF24: 0.0414 | AG24: 0.0434 | AH24: 0.0434 | AI24: 0.042 | BA24: 1
C25: 32 | D25: 개월 | E25: 0.015 | F25: 0.015 | G25: 0.017 | H25: 0.017 | I25: 0.019 | J25: 0.019 | K25: 0.024 | L25: 0.024 | M25: 0.027 | N25: 0.027 | O25: 0.03 | P25: 0.03 | Q25: 0.032 | R25: 0.032 | S25: 0.034 | T25: 0.034 | U25: 0.034 | V25: 0.034 | W25: 0.034 | X25: 0.034 | Y25: 0.036 | Z25: 0.036 | AA25: 0.036 | AB25: 0.036 | AC25: 0.038 | AD25: 0.038 | AE25: 0.04 | AF25: 0.04 | AG25: 0.042 | AH25: 0.042 | AI25: 0.042 | AJ25: 0.042 | BA25: 1
C26: 33 | D26: 개월 | E26: 0.0139 | F26: 0.0139 | G26: 0.0159 | H26: 0.0159 | I26: 0.0179 | J26: 0.0179 | K26: 0.0229 | L26: 0.0229 | M26: 0.0259 | N26: 0.0259 | O26: 0.0289 | P26: 0.0289 | Q26: 0.0309 | R26: 0.0309 | S26: 0.0329 | T26: 0.0329 | U26: 0.0329 | V26: 0.0329 | W26: 0.0329 | X26: 0.0329 | Y26: 0.0349 | Z26: 0.0349 | AA26: 0.0349 | AB26: 0.0349 | AC26: 0.0369 | AD26: 0.0369 | AE26: 0.0389 | AF26: 0.0389 | AG26: 0.0409 | AH26: 0.0409 | AI26: 0.0409 | AJ26: 0.0409 | AK26: 0.0352 | BA26: 1
C27: 34 | D27: 개월 | E27: 0.0129 | F27: 0.0129 | G27: 0.0149 | H27: 0.0149 | I27: 0.0169 | J27: 0.0169 | K27: 0.0219 | L27: 0.0219 | M27: 0.0249 | N27: 0.0249 | O27: 0.0279 | P27: 0.0279 | Q27: 0.0299 | R27: 0.0299 | S27: 0.0319 | T27: 0.0319 | U27: 0.0319 | V27: 0.0319 | W27: 0.0319 | X27: 0.0319 | Y27: 0.0339 | Z27: 0.0339 | AA27: 0.0339 | AB27: 0.0339 | AC27: 0.0359 | AD27: 0.0359 | AE27: 0.0379 | AF27: 0.0379 | AG27: 0.0399 | AH27: 0.0399 | AI27: 0.0399 | AJ27: 0.0399 | AK27: 0.0379 | AL27: 0.0293 | BA27: 1
C28: 35 | D28: 개월 | E28: 0.0117 | F28: 0.0117 | G28: 0.0137 | H28: 0.0137 | I28: 0.0157 | J28: 0.0157 | K28: 0.0207 | L28: 0.0207 | M28: 0.0237 | N28: 0.0237 | O28: 0.0267 | P28: 0.0267 | Q28: 0.0287 | R28: 0.0287 | S28: 0.0307 | T28: 0.0307 | U28: 0.0307 | V28: 0.0307 | W28: 0.0307 | X28: 0.0307 | Y28: 0.0327 | Z28: 0.0327 | AA28: 0.0327 | AB28: 0.0327 | AC28: 0.0347 | AD28: 0.0347 | AE28: 0.0367 | AF28: 0.0367 | AG28: 0.0387 | AH28: 0.0387 | AI28: 0.0387 | AJ28: 0.0387 | AK28: 0.0367 | AL28: 0.0367 | AM28: 0.0322 | BA28: 1
C29: 36 | D29: 개월 | E29: 0.0105 | F29: 0.0105 | G29: 0.0125 | H29: 0.0125 | I29: 0.0145 | J29: 0.0145 | K29: 0.0195 | L29: 0.0195 | M29: 0.0225 | N29: 0.0225 | O29: 0.0255 | P29: 0.0255 | Q29: 0.0275 | R29: 0.0275 | S29: 0.0295 | T29: 0.0295 | U29: 0.0295 | V29: 0.0295 | W29: 0.0295 | X29: 0.0295 | Y29: 0.0315 | Z29: 0.0315 | AA29: 0.0315 | AB29: 0.0315 | AC29: 0.0335 | AD29: 0.0335 | AE29: 0.0355 | AF29: 0.0355 | AG29: 0.0375 | AH29: 0.0375 | AI29: 0.0375 | AJ29: 0.0375 | AK29: 0.0355 | AL29: 0.0355 | AM29: 0.0355 | AN29: 0.0375 | BA29: 1
C30: 37 | D30: 개월 | E30: 0.0096 | F30: 0.0096 | G30: 0.0116 | H30: 0.0116 | I30: 0.0136 | J30: 0.0136 | K30: 0.0186 | L30: 0.0186 | M30: 0.0216 | N30: 0.0216 | O30: 0.0246 | P30: 0.0246 | Q30: 0.0266 | R30: 0.0266 | S30: 0.0286 | T30: 0.0286 | U30: 0.0286 | V30: 0.0286 | W30: 0.0286 | X30: 0.0286 | Y30: 0.0306 | Z30: 0.0306 | AA30: 0.0306 | AB30: 0.0306 | AC30: 0.0326 | AD30: 0.0326 | AE30: 0.0346 | AF30: 0.0346 | AG30: 0.0366 | AH30: 0.0366 | AI30: 0.0366 | AJ30: 0.0366 | AK30: 0.0346 | AL30: 0.0346 | AM30: 0.0346 | AN30: 0.0346 | AO30: 0.0344 | BA30: 1
C31: 38 | D31: 개월 | E31: 0.0088 | F31: 0.0088 | G31: 0.0108 | H31: 0.0108 | I31: 0.0128 | J31: 0.0128 | K31: 0.0178 | L31: 0.0178 | M31: 0.0208 | N31: 0.0208 | O31: 0.0238 | P31: 0.0238 | Q31: 0.0258 | R31: 0.0258 | S31: 0.0278 | T31: 0.0278 | U31: 0.0278 | V31: 0.0278 | W31: 0.0278 | X31: 0.0278 | Y31: 0.0298 | Z31: 0.0298 | AA31: 0.0298 | AB31: 0.0298 | AC31: 0.0318 | AD31: 0.0318 | AE31: 0.0338 | AF31: 0.0338 | AG31: 0.0358 | AH31: 0.0358 | AI31: 0.0358 | AJ31: 0.0358 | AK31: 0.0338 | AL31: 0.0338 | AM31: 0.0338 | AN31: 0.0338 | AO31: 0.0318 | AP31: 0.0314 | BA31: 1
C32: 39 | D32: 개월 | E32: 0.008 | F32: 0.008 | G32: 0.01 | H32: 0.01 | I32: 0.012 | J32: 0.012 | K32: 0.017 | L32: 0.017 | M32: 0.02 | N32: 0.02 | O32: 0.023 | P32: 0.023 | Q32: 0.025 | R32: 0.025 | S32: 0.027 | T32: 0.027 | U32: 0.027 | V32: 0.027 | W32: 0.027 | X32: 0.027 | Y32: 0.029 | Z32: 0.029 | AA32: 0.029 | AB32: 0.029 | AC32: 0.031 | AD32: 0.031 | AE32: 0.033 | AF32: 0.033 | AG32: 0.035 | AH32: 0.035 | AI32: 0.035 | AJ32: 0.035 | AK32: 0.033 | AL32: 0.033 | AM32: 0.033 | AN32: 0.033 | AO32: 0.031 | AP32: 0.031 | AQ32: 0.03 | BA32: 1
C33: 40 | D33: 개월 | E33: 0.00735 | F33: 0.00735 | G33: 0.00935 | H33: 0.00935 | I33: 0.01135 | J33: 0.01135 | K33: 0.01635 | L33: 0.01635 | M33: 0.01935 | N33: 0.01935 | O33: 0.02235 | P33: 0.02235 | Q33: 0.02435 | R33: 0.02435 | S33: 0.02635 | T33: 0.02635 | U33: 0.02635 | V33: 0.02635 | W33: 0.02635 | X33: 0.02635 | Y33: 0.02835 | Z33: 0.02835 | AA33: 0.02835 | AB33: 0.02835 | AC33: 0.03035 | AD33: 0.03035 | AE33: 0.03235 | AF33: 0.03235 | AG33: 0.03435 | AH33: 0.03435 | AI33: 0.03435 | AJ33: 0.03435 | AK33: 0.03235 | AL33: 0.03235 | AM33: 0.03235 | AN33: 0.03235 | AO33: 0.03035 | AP33: 0.03035 | AQ33: 0.02735 | AR33: 0.02735 | BA33: 1
C34: 41 | D34: 개월 | E34: 0.0067 | F34: 0.0067 | G34: 0.0087 | H34: 0.0087 | I34: 0.0107 | J34: 0.0107 | K34: 0.0157 | L34: 0.0157 | M34: 0.0187 | N34: 0.0187 | O34: 0.0217 | P34: 0.0217 | Q34: 0.0237 | R34: 0.0237 | S34: 0.0257 | T34: 0.0257 | U34: 0.0257 | V34: 0.0257 | W34: 0.0257 | X34: 0.0257 | Y34: 0.0277 | Z34: 0.0277 | AA34: 0.0277 | AB34: 0.0277 | AC34: 0.0297 | AD34: 0.0297 | AE34: 0.0317 | AF34: 0.0317 | AG34: 0.0337 | AH34: 0.0337 | AI34: 0.0337 | AJ34: 0.0337 | AK34: 0.0317 | AL34: 0.0317 | AM34: 0.0317 | AN34: 0.0317 | AO34: 0.0297 | AP34: 0.0297 | AQ34: 0.0267 | AR34: 0.0267 | AS34: 0.026 | BA34: 1
C35: 42 | D35: 개월 | E35: 0.0062 | F35: 0.0062 | G35: 0.0082 | H35: 0.0082 | I35: 0.0102 | J35: 0.0102 | K35: 0.0152 | L35: 0.0152 | M35: 0.0182 | N35: 0.0182 | O35: 0.0212 | P35: 0.0212 | Q35: 0.0232 | R35: 0.0232 | S35: 0.0252 | T35: 0.0252 | U35: 0.0252 | V35: 0.0252 | W35: 0.0252 | X35: 0.0252 | Y35: 0.0272 | Z35: 0.0272 | AA35: 0.0272 | AB35: 0.0272 | AC35: 0.0292 | AD35: 0.0292 | AE35: 0.0312 | AF35: 0.0312 | AG35: 0.0332 | AH35: 0.0332 | AI35: 0.0332 | AJ35: 0.0332 | AK35: 0.0312 | AL35: 0.0312 | AM35: 0.0312 | AN35: 0.0312 | AO35: 0.0292 | AP35: 0.0292 | AQ35: 0.0262 | AR35: 0.0262 | AS35: 0.0232 | AT35: 0.0228 | BA35: 1
C36: 43 | D36: 개월 | E36: 0.0057 | F36: 0.0057 | G36: 0.0077 | H36: 0.0077 | I36: 0.0097 | J36: 0.0097 | K36: 0.0147 | L36: 0.0147 | M36: 0.0177 | N36: 0.0177 | O36: 0.0207 | P36: 0.0207 | Q36: 0.0227 | R36: 0.0227 | S36: 0.0247 | T36: 0.0247 | U36: 0.0247 | V36: 0.0247 | W36: 0.0247 | X36: 0.0247 | Y36: 0.0267 | Z36: 0.0267 | AA36: 0.0267 | AB36: 0.0267 | AC36: 0.0287 | AD36: 0.0287 | AE36: 0.0307 | AF36: 0.0307 | AG36: 0.0327 | AH36: 0.0327 | AI36: 0.0327 | AJ36: 0.0327 | AK36: 0.0307 | AL36: 0.0307 | AM36: 0.0307 | AN36: 0.0307 | AO36: 0.0287 | AP36: 0.0287 | AQ36: 0.0257 | AR36: 0.0257 | AS36: 0.0227 | AT36: 0.0227 | AU36: 0.0206 | BA36: 1
C37: 44 | D37: 개월 | E37: 0.00535 | F37: 0.00535 | G37: 0.00735 | H37: 0.00735 | I37: 0.00935 | J37: 0.00935 | K37: 0.01435 | L37: 0.01435 | M37: 0.01735 | N37: 0.01735 | O37: 0.02035 | P37: 0.02035 | Q37: 0.02235 | R37: 0.02235 | S37: 0.02435 | T37: 0.02435 | U37: 0.02435 | V37: 0.02435 | W37: 0.02435 | X37: 0.02435 | Y37: 0.02635 | Z37: 0.02635 | AA37: 0.02635 | AB37: 0.02635 | AC37: 0.02835 | AD37: 0.02835 | AE37: 0.03035 | AF37: 0.03035 | AG37: 0.03235 | AH37: 0.03235 | AI37: 0.03235 | AJ37: 0.03235 | AK37: 0.03035 | AL37: 0.03035 | AM37: 0.03035 | AN37: 0.03035 | AO37: 0.02835 | AP37: 0.02835 | AQ37: 0.02535 | AR37: 0.02535 | AS37: 0.02235 | AT37: 0.02235 | AU37: 0.01935 | AV37: 0.01595 | BA37: 1
C38: 45 | D38: 개월 | E38: 0.0049 | F38: 0.0049 | G38: 0.0069 | H38: 0.0069 | I38: 0.0089 | J38: 0.0089 | K38: 0.0139 | L38: 0.0139 | M38: 0.0169 | N38: 0.0169 | O38: 0.0199 | P38: 0.0199 | Q38: 0.0219 | R38: 0.0219 | S38: 0.0239 | T38: 0.0239 | U38: 0.0239 | V38: 0.0239 | W38: 0.0239 | X38: 0.0239 | Y38: 0.0259 | Z38: 0.0259 | AA38: 0.0259 | AB38: 0.0259 | AC38: 0.0279 | AD38: 0.0279 | AE38: 0.0299 | AF38: 0.0299 | AG38: 0.0319 | AH38: 0.0319 | AI38: 0.0319 | AJ38: 0.0319 | AK38: 0.0299 | AL38: 0.0299 | AM38: 0.0299 | AN38: 0.0299 | AO38: 0.0279 | AP38: 0.0279 | AQ38: 0.0249 | AR38: 0.0249 | AS38: 0.0219 | AT38: 0.0219 | AU38: 0.0189 | AV38: 0.0189 | AW38: 0.0164 | BA38: 1
